<?xml version='1.0' encoding='utf-8'?>
<robot name="g1_29dof">
  <link name="pelvis">
    <inertial>
      <origin xyz="0 0 -0.07605" rpy="0 0 0" />
      <mass value="3.813" />
      <inertia ixx="0.010549" ixy="0" ixz="2.1E-06" iyy="0.0093089" iyz="0" izz="0.0079184" />
    </inertial>
    <visual>
      <origin xyz="0 0 0" rpy="0 0 0" />
      <geometry>
        <mesh filename="../mesh/G1/pelvis.stl" />
      </geometry>
      <material name="dark">
        <color rgba="0.2 0.2 0.2 1" />
      </material>
    </visual>
  </link>
  <link name="pelvis_contour_link">
    <inertial>
      <origin xyz="0 0 0" rpy="0 0 0" />
      <mass value="0.001" />
      <inertia ixx="1e-7" ixy="0" ixz="0" iyy="1e-7" iyz="0" izz="1e-7" />
    </inertial>
    <visual>
      <origin xyz="0 0 0" rpy="0 0 0" />
      <geometry>
        <mesh filename="../mesh/G1/pelvis_contour_link.stl" />
      </geometry>
      <material name="white">
        <color rgba="0.7 0.7 0.7 1" />
      </material>
    </visual>
    <collision>
      <origin xyz="0 0 0" rpy="0 0 0" />
      <geometry>
        <mesh filename="../mesh/G1/pelvis_contour_link.stl" />
      </geometry>
    </collision>
  </link>
  <joint name="pelvis_contour_joint" type="fixed">
    <parent link="pelvis" />
    <child link="pelvis_contour_link" />
  </joint>
  <link name="left_hip_pitch_link">
    <inertial>
      <origin xyz="0.002741 0.047791 -0.02606" rpy="0 0 0" />
      <mass value="1.35" />
      <inertia ixx="0.001811" ixy="3.68E-05" ixz="-3.44E-05" iyy="0.0014193" iyz="0.000171" izz="0.0012812" />
    </inertial>
    <visual>
      <origin xyz="0 0 0" rpy="0 0 0" />
      <geometry>
        <mesh filename="../mesh/G1/left_hip_pitch_link.stl" />
      </geometry>
      <material name="dark">
        <color rgba="0.2 0.2 0.2 1" />
      </material>
    </visual>
    <collision>
      <origin xyz="0 0 0" rpy="0 0 0" />
      <geometry>
        <mesh filename="../mesh/G1/left_hip_pitch_link.stl" />
      </geometry>
    </collision>
  </link>
  <joint name="left_hip_pitch_joint" type="revolute">
    <origin xyz="0 0.064452 -0.1027" rpy="0 0 0" />
    <parent link="pelvis" />
    <child link="left_hip_pitch_link" />
    <axis xyz="0 1 0" />
    <limit lower="-2.5307" upper="2.8798" effort="88" velocity="32" />
  </joint>
  <link name="left_hip_roll_link">
    <inertial>
      <origin xyz="0.029812 -0.001045 -0.087934" rpy="0 0 0" />
      <mass value="1.52" />
      <inertia ixx="0.0023773" ixy="-3.8E-06" ixz="-0.0003908" iyy="0.0024123" iyz="1.84E-05" izz="0.0016595" />
    </inertial>
    <visual>
      <origin xyz="0 0 0" rpy="0 0 0" />
      <geometry>
        <mesh filename="../mesh/G1/left_hip_roll_link.stl" />
      </geometry>
      <material name="white">
        <color rgba="0.7 0.7 0.7 1" />
      </material>
    </visual>
    <collision>
      <origin xyz="0 0 0" rpy="0 0 0" />
      <geometry>
        <mesh filename="../mesh/G1/left_hip_roll_link.stl" />
      </geometry>
    </collision>
  </link>
  <joint name="left_hip_roll_joint" type="revolute">
    <origin xyz="0 0.052 -0.030465" rpy="0 -0.1749 0" />
    <parent link="left_hip_pitch_link" />
    <child link="left_hip_roll_link" />
    <axis xyz="1 0 0" />
    <limit lower="-0.5236" upper="2.9671" effort="88" velocity="32" />
  </joint>
  <link name="left_hip_yaw_link">
    <inertial>
      <origin xyz="-0.057709 -0.010981 -0.15078" rpy="0 0 0" />
      <mass value="1.702" />
      <inertia ixx="0.0057774" ixy="-0.0005411" ixz="-0.0023948" iyy="0.0076124" iyz="-0.0007072" izz="0.003149" />
    </inertial>
    <visual>
      <origin xyz="0 0 0" rpy="0 0 0" />
      <geometry>
        <mesh filename="../mesh/G1/left_hip_yaw_link.stl" />
      </geometry>
      <material name="white">
        <color rgba="0.7 0.7 0.7 1" />
      </material>
    </visual>
    <collision>
      <origin xyz="0 0 0" rpy="0 0 0" />
      <geometry>
        <mesh filename="../mesh/G1/left_hip_yaw_link.stl" />
      </geometry>
    </collision>
  </link>
  <joint name="left_hip_yaw_joint" type="revolute">
    <origin xyz="0.025001 0 -0.12412" rpy="0 0 0" />
    <parent link="left_hip_roll_link" />
    <child link="left_hip_yaw_link" />
    <axis xyz="0 0 1" />
    <limit lower="-2.7576" upper="2.7576" effort="88" velocity="32" />
  </joint>
  <link name="left_knee_link">
    <inertial>
      <origin xyz="0.005457 0.003964 -0.12074" rpy="0 0 0" />
      <mass value="1.932" />
      <inertia ixx="0.011329" ixy="4.82E-05" ixz="-4.49E-05" iyy="0.011277" iyz="-0.0007146" izz="0.0015168" />
    </inertial>
    <visual>
      <origin xyz="0 0 0" rpy="0 0 0" />
      <geometry>
        <mesh filename="../mesh/G1/left_knee_link.stl" />
      </geometry>
      <material name="white">
        <color rgba="0.7 0.7 0.7 1" />
      </material>
    </visual>
    <collision>
      <origin xyz="0 0 0" rpy="0 0 0" />
      <geometry>
        <mesh filename="../mesh/G1/left_knee_link.stl" />
      </geometry>
    </collision>
  </link>
  <joint name="left_knee_joint" type="revolute">
    <origin xyz="-0.078273 0.0021489 -0.17734" rpy="0 0.1749 0" />
    <parent link="left_hip_yaw_link" />
    <child link="left_knee_link" />
    <axis xyz="0 1 0" />
    <limit lower="-0.087267" upper="2.8798" effort="139" velocity="20" />
  </joint>
  <link name="left_ankle_pitch_link">
    <inertial>
      <origin xyz="-0.007269 0 0.011137" rpy="0 0 0" />
      <mass value="0.074" />
      <inertia ixx="8.4E-06" ixy="0" ixz="-2.9E-06" iyy="1.89E-05" iyz="0" izz="1.26E-05" />
    </inertial>
    <visual>
      <origin xyz="0 0 0" rpy="0 0 0" />
      <geometry>
        <mesh filename="../mesh/G1/left_ankle_pitch_link.stl" />
      </geometry>
      <material name="white">
        <color rgba="0.7 0.7 0.7 1" />
      </material>
    </visual>
    <collision>
      <origin xyz="0 0 0" rpy="0 0 0" />
      <geometry>
        <mesh filename="../mesh/G1/left_ankle_pitch_link.stl" />
      </geometry>
    </collision>
  </link>
  <joint name="left_ankle_pitch_joint" type="revolute">
    <origin xyz="0 -9.4445E-05 -0.30001" rpy="0 0 0" />
    <parent link="left_knee_link" />
    <child link="left_ankle_pitch_link" />
    <axis xyz="0 1 0" />
    <limit lower="-0.87267" upper="0.5236" effort="50" velocity="37" />
  </joint>
  <link name="left_ankle_roll_link">
    <inertial>
      <origin xyz="0.026505 0 -0.016425" rpy="0 0 0" />
      <mass value="0.608" />
      <inertia ixx="0.0002231" ixy="2E-07" ixz="8.91E-05" iyy="0.0016161" iyz="-1E-07" izz="0.0016667" />
    </inertial>
    <visual>
      <origin xyz="0 0 0" rpy="0 0 0" />
      <geometry>
        <mesh filename="../mesh/G1/left_ankle_roll_link.stl" />
      </geometry>
      <material name="dark">
        <color rgba="0.2 0.2 0.2 1" />
      </material>
    </visual>
    <collision>
      <origin xyz="-0.05 0.025 -0.03" rpy="0 0 0" />
      <geometry>
        <sphere radius="0.005" />
      </geometry>
    </collision>
    <collision>
      <origin xyz="-0.05 -0.025 -0.03" rpy="0 0 0" />
      <geometry>
        <sphere radius="0.005" />
      </geometry>
    </collision>
    <collision>
      <origin xyz="0.12 0.03 -0.03" rpy="0 0 0" />
      <geometry>
        <sphere radius="0.005" />
      </geometry>
    </collision>
    <collision>
      <origin xyz="0.12 -0.03 -0.03" rpy="0 0 0" />
      <geometry>
        <sphere radius="0.005" />
      </geometry>
    </collision>
  </link>
  <joint name="left_ankle_roll_joint" type="revolute">
    <origin xyz="0 0 -0.017558" rpy="0 0 0" />
    <parent link="left_ankle_pitch_link" />
    <child link="left_ankle_roll_link" />
    <axis xyz="1 0 0" />
    <limit lower="-0.2618" upper="0.2618" effort="50" velocity="37" />
  </joint>
  <link name="right_hip_pitch_link">
    <inertial>
      <origin xyz="0.002741 -0.047791 -0.02606" rpy="0 0 0" />
      <mass value="1.35" />
      <inertia ixx="0.001811" ixy="-3.68E-05" ixz="-3.44E-05" iyy="0.0014193" iyz="-0.000171" izz="0.0012812" />
    </inertial>
    <visual>
      <origin xyz="0 0 0" rpy="0 0 0" />
      <geometry>
        <mesh filename="../mesh/G1/right_hip_pitch_link.stl" />
      </geometry>
      <material name="dark">
        <color rgba="0.2 0.2 0.2 1" />
      </material>
    </visual>
    <collision>
      <origin xyz="0 0 0" rpy="0 0 0" />
      <geometry>
        <mesh filename="../mesh/G1/right_hip_pitch_link.stl" />
      </geometry>
    </collision>
  </link>
  <joint name="right_hip_pitch_joint" type="revolute">
    <origin xyz="0 -0.064452 -0.1027" rpy="0 0 0" />
    <parent link="pelvis" />
    <child link="right_hip_pitch_link" />
    <axis xyz="0 1 0" />
    <limit lower="-2.5307" upper="2.8798" effort="88" velocity="32" />
  </joint>
  <link name="right_hip_roll_link">
    <inertial>
      <origin xyz="0.029812 0.001045 -0.087934" rpy="0 0 0" />
      <mass value="1.52" />
      <inertia ixx="0.0023773" ixy="3.8E-06" ixz="-0.0003908" iyy="0.0024123" iyz="-1.84E-05" izz="0.0016595" />
    </inertial>
    <visual>
      <origin xyz="0 0 0" rpy="0 0 0" />
      <geometry>
        <mesh filename="../mesh/G1/right_hip_roll_link.stl" />
      </geometry>
      <material name="white">
        <color rgba="0.7 0.7 0.7 1" />
      </material>
    </visual>
    <collision>
      <origin xyz="0 0 0" rpy="0 0 0" />
      <geometry>
        <mesh filename="../mesh/G1/right_hip_roll_link.stl" />
      </geometry>
    </collision>
  </link>
  <joint name="right_hip_roll_joint" type="revolute">
    <origin xyz="0 -0.052 -0.030465" rpy="0 -0.1749 0" />
    <parent link="right_hip_pitch_link" />
    <child link="right_hip_roll_link" />
    <axis xyz="1 0 0" />
    <limit lower="-2.9671" upper="0.5236" effort="88" velocity="32" />
  </joint>
  <link name="right_hip_yaw_link">
    <inertial>
      <origin xyz="-0.057709 0.010981 -0.15078" rpy="0 0 0" />
      <mass value="1.702" />
      <inertia ixx="0.0057774" ixy="0.0005411" ixz="-0.0023948" iyy="0.0076124" iyz="0.0007072" izz="0.003149" />
    </inertial>
    <visual>
      <origin xyz="0 0 0" rpy="0 0 0" />
      <geometry>
        <mesh filename="../mesh/G1/right_hip_yaw_link.stl" />
      </geometry>
      <material name="white">
        <color rgba="0.7 0.7 0.7 1" />
      </material>
    </visual>
    <collision>
      <origin xyz="0 0 0" rpy="0 0 0" />
      <geometry>
        <mesh filename="../mesh/G1/right_hip_yaw_link.stl" />
      </geometry>
    </collision>
  </link>
  <joint name="right_hip_yaw_joint" type="revolute">
    <origin xyz="0.025001 0 -0.12412" rpy="0 0 0" />
    <parent link="right_hip_roll_link" />
    <child link="right_hip_yaw_link" />
    <axis xyz="0 0 1" />
    <limit lower="-2.7576" upper="2.7576" effort="88" velocity="32" />
  </joint>
  <link name="right_knee_link">
    <inertial>
      <origin xyz="0.005457 -0.003964 -0.12074" rpy="0 0 0" />
      <mass value="1.932" />
      <inertia ixx="0.011329" ixy="-4.82E-05" ixz="4.49E-05" iyy="0.011277" iyz="0.0007146" izz="0.0015168" />
    </inertial>
    <visual>
      <origin xyz="0 0 0" rpy="0 0 0" />
      <geometry>
        <mesh filename="../mesh/G1/right_knee_link.stl" />
      </geometry>
      <material name="white">
        <color rgba="0.7 0.7 0.7 1" />
      </material>
    </visual>
    <collision>
      <origin xyz="0 0 0" rpy="0 0 0" />
      <geometry>
        <mesh filename="../mesh/G1/right_knee_link.stl" />
      </geometry>
    </collision>
  </link>
  <joint name="right_knee_joint" type="revolute">
    <origin xyz="-0.078273 -0.0021489 -0.17734" rpy="0 0.1749 0" />
    <parent link="right_hip_yaw_link" />
    <child link="right_knee_link" />
    <axis xyz="0 1 0" />
    <limit lower="-0.087267" upper="2.8798" effort="139" velocity="20" />
  </joint>
  <link name="right_ankle_pitch_link">
    <inertial>
      <origin xyz="-0.007269 0 0.011137" rpy="0 0 0" />
      <mass value="0.074" />
      <inertia ixx="8.4E-06" ixy="0" ixz="-2.9E-06" iyy="1.89E-05" iyz="0" izz="1.26E-05" />
    </inertial>
    <visual>
      <origin xyz="0 0 0" rpy="0 0 0" />
      <geometry>
        <mesh filename="../mesh/G1/right_ankle_pitch_link.stl" />
      </geometry>
      <material name="white">
        <color rgba="0.7 0.7 0.7 1" />
      </material>
    </visual>
    <collision>
      <origin xyz="0 0 0" rpy="0 0 0" />
      <geometry>
        <mesh filename="../mesh/G1/right_ankle_pitch_link.stl" />
      </geometry>
    </collision>
  </link>
  <joint name="right_ankle_pitch_joint" type="revolute">
    <origin xyz="0 9.4445E-05 -0.30001" rpy="0 0 0" />
    <parent link="right_knee_link" />
    <child link="right_ankle_pitch_link" />
    <axis xyz="0 1 0" />
    <limit lower="-0.87267" upper="0.5236" effort="50" velocity="37" />
  </joint>
  <link name="right_ankle_roll_link">
    <inertial>
      <origin xyz="0.026505 0 -0.016425" rpy="0 0 0" />
      <mass value="0.608" />
      <inertia ixx="0.0002231" ixy="-2E-07" ixz="8.91E-05" iyy="0.0016161" iyz="1E-07" izz="0.0016667" />
    </inertial>
    <visual>
      <origin xyz="0 0 0" rpy="0 0 0" />
      <geometry>
        <mesh filename="../mesh/G1/right_ankle_roll_link.stl" />
      </geometry>
      <material name="dark">
        <color rgba="0.2 0.2 0.2 1" />
      </material>
    </visual>
    <collision>
      <origin xyz="-0.05 0.025 -0.03" rpy="0 0 0" />
      <geometry>
        <sphere radius="0.005" />
      </geometry>
    </collision>
    <collision>
      <origin xyz="-0.05 -0.025 -0.03" rpy="0 0 0" />
      <geometry>
        <sphere radius="0.005" />
      </geometry>
    </collision>
    <collision>
      <origin xyz="0.12 0.03 -0.03" rpy="0 0 0" />
      <geometry>
        <sphere radius="0.005" />
      </geometry>
    </collision>
    <collision>
      <origin xyz="0.12 -0.03 -0.03" rpy="0 0 0" />
      <geometry>
        <sphere radius="0.005" />
      </geometry>
    </collision>
  </link>
  <joint name="right_ankle_roll_joint" type="revolute">
    <origin xyz="0 0 -0.017558" rpy="0 0 0" />
    <parent link="right_ankle_pitch_link" />
    <child link="right_ankle_roll_link" />
    <axis xyz="1 0 0" />
    <limit lower="-0.2618" upper="0.2618" effort="50" velocity="37" />
  </joint>
  <link name="waist_yaw_link">
    <inertial>
      <origin xyz="0.003964 0 0.018769" rpy="0 0 0" />
      <mass value="0.244" />
      <inertia ixx="9.9587E-05" ixy="-1.833E-06" ixz="-1.2617E-05" iyy="0.00012411" iyz="-1.18E-07" izz="0.00015586" />
    </inertial>
    <visual>
      <origin xyz="0 0 0" rpy="0 0 0" />
      <geometry>
        <mesh filename="../mesh/G1/waist_yaw_link.stl" />
      </geometry>
      <material name="white">
        <color rgba="0.7 0.7 0.7 1" />
      </material>
    </visual>
  </link>
  <joint name="waist_yaw_joint" type="revolute">
    <origin xyz="0 0 0" rpy="0 0 0" />
    <parent link="pelvis" />
    <child link="waist_yaw_link" />
    <axis xyz="0 0 1" />
    <limit lower="-2.618" upper="2.618" effort="88" velocity="32" />
  </joint>
  <link name="waist_roll_link">
    <inertial>
      <origin xyz="0 -0.000236 0.010111" rpy="0 0 0" />
      <mass value="0.047" />
      <inertia ixx="7.515E-06" ixy="0" ixz="0" iyy="6.398E-06" iyz="9.9E-08" izz="3.988E-06" />
    </inertial>
    <visual>
      <origin xyz="0 0 0" rpy="0 0 0" />
      <geometry>
        <mesh filename="../mesh/G1/waist_roll_link.stl" />
      </geometry>
      <material name="white">
        <color rgba="0.7 0.7 0.7 1" />
      </material>
    </visual>
  </link>
  <joint name="waist_roll_joint" type="revolute">
    <origin xyz="-0.0039635 0 0.035" rpy="0 0 0" />
    <parent link="waist_yaw_link" />
    <child link="waist_roll_link" />
    <axis xyz="1 0 0" />
    <limit lower="-0.52" upper="0.52" effort="50" velocity="37" />
  </joint>
  <link name="torso_link">
    <inertial>
      <origin xyz="0.002601 0.000257 0.153719" rpy="0 0 0" />
      <mass value="8.562" />
      <inertia ixx="0.065674966" ixy="-8.597E-05" ixz="-0.001737252" iyy="0.053535188" iyz="8.6899E-05" izz="0.030808125" />
    </inertial>
    <visual>
      <origin xyz="0 0 0" rpy="0 0 0" />
      <geometry>
        <mesh filename="../mesh/G1/torso_link.stl" />
      </geometry>
      <material name="white">
        <color rgba="0.7 0.7 0.7 1" />
      </material>
    </visual>
    <collision>
      <origin xyz="0 0 0" rpy="0 0 0" />
      <geometry>
        <mesh filename="../mesh/G1/torso_link.stl" />
      </geometry>
    </collision>
  </link>
  <joint name="waist_pitch_joint" type="revolute">
    <origin xyz="0 0 0.019" rpy="0 0 0" />
    <parent link="waist_roll_link" />
    <child link="torso_link" />
    <axis xyz="0 1 0" />
    <limit lower="-0.52" upper="0.52" effort="50" velocity="37" />
  </joint>
  <joint name="logo_joint" type="fixed">
    <origin xyz="0.0039635 0 -0.054" rpy="0 0 0" />
    <parent link="torso_link" />
    <child link="logo_link" />
  </joint>
  <link name="logo_link">
    <inertial>
      <origin xyz="0 0 0" rpy="0 0 0" />
      <mass value="0.001" />
      <inertia ixx="1e-7" ixy="0" ixz="0" iyy="1e-7" iyz="0" izz="1e-7" />
    </inertial>
    <visual>
      <origin xyz="0 0 0" rpy="0 0 0" />
      <geometry>
        <mesh filename="../mesh/G1/logo_link.stl" />
      </geometry>
      <material name="dark">
        <color rgba="0.2 0.2 0.2 1" />
      </material>
    </visual>
    <collision>
      <origin xyz="0 0 0" rpy="0 0 0" />
      <geometry>
        <mesh filename="../mesh/G1/logo_link.stl" />
      </geometry>
    </collision>
  </link>
  <link name="head_link">
    <inertial>
      <origin xyz="0.005267 0.000299 0.449869" rpy="0 0 0" />
      <mass value="1.036" />
      <inertia ixx="0.004085051" ixy="-2.543E-06" ixz="-6.9455E-05" iyy="0.004185212" iyz="-3.726E-06" izz="0.001807911" />
    </inertial>
    <visual>
      <origin xyz="0 0 0" rpy="0 0 0" />
      <geometry>
        <mesh filename="../mesh/G1/head_link.stl" />
      </geometry>
      <material name="dark">
        <color rgba="0.2 0.2 0.2 1" />
      </material>
    </visual>
    <collision>
      <origin xyz="0 0 0" rpy="0 0 0" />
      <geometry>
        <mesh filename="../mesh/G1/head_link.stl" />
      </geometry>
    </collision>
  </link>
  <joint name="head_joint" type="fixed">
    <origin xyz="0.0039635 0 -0.054" rpy="0 0 0" />
    <parent link="torso_link" />
    <child link="head_link" />
  </joint>
  <link name="waist_support_link">
    <inertial>
      <origin xyz="0 0 0" rpy="0 0 0" />
      <mass value="0.001" />
      <inertia ixx="1e-7" ixy="0" ixz="0" iyy="1e-7" iyz="0" izz="1e-7" />
    </inertial>
    <visual>
      <origin xyz="0 0 0" rpy="0 0 0" />
      <geometry>
        <mesh filename="../mesh/G1/waist_support_link.stl" />
      </geometry>
      <material name="white">
        <color rgba="0.7 0.7 0.7 1" />
      </material>
    </visual>
    <collision>
      <origin xyz="0 0 0" rpy="0 0 0" />
      <geometry>
        <mesh filename="../mesh/G1/waist_support_link.stl" />
      </geometry>
    </collision>
  </link>
  <joint name="waist_support_joint" type="fixed">
    <origin xyz="0.0039635 0 -0.054" rpy="0 0 0" />
    <parent link="torso_link" />
    <child link="waist_support_link" />
  </joint>
  <link name="imu_link" />
  <joint name="imu_joint" type="fixed">
    <origin xyz="-0.03959 -0.00224 0.13792" rpy="0 0 0" />
    <parent link="torso_link" />
    <child link="imu_link" />
  </joint>
  <link name="d435_link" />
  <joint name="d435_joint" type="fixed">
    <origin xyz="0.0576235 0.01753 0.41987" rpy="0 0.8307767239493009 0" />
    <parent link="torso_link" />
    <child link="d435_link" />
  </joint>
  <link name="mid360_link" />
  <joint name="mid360_joint" type="fixed">
    <origin xyz="0.0002835 0.00003 0.40618" rpy="0 0.04014257279586953 0" />
    <parent link="torso_link" />
    <child link="mid360_link" />
  </joint>
  <link name="left_shoulder_pitch_link">
    <inertial>
      <origin xyz="0 0.035892 -0.011628" rpy="0 0 0" />
      <mass value="0.718" />
      <inertia ixx="0.0004291" ixy="-9.2E-06" ixz="6.4E-06" iyy="0.000453" iyz="2.26E-05" izz="0.000423" />
    </inertial>
    <visual>
      <origin xyz="0 0 0" rpy="0 0 0" />
      <geometry>
        <mesh filename="../mesh/G1/left_shoulder_pitch_link.stl" />
      </geometry>
      <material name="white">
        <color rgba="0.7 0.7 0.7 1" />
      </material>
    </visual>
    <collision>
      <origin xyz="0 0.04 -0.01" rpy="0 1.5707963267948966 0" />
      <geometry>
        <cylinder radius="0.03" length="0.05" />
      </geometry>
    </collision>
  </link>
  <joint name="left_shoulder_pitch_joint" type="revolute">
    <origin xyz="0.0039563 0.10022 0.23778" rpy="0.27931 5.4949E-05 -0.00019159" />
    <parent link="torso_link" />
    <child link="left_shoulder_pitch_link" />
    <axis xyz="0 1 0" />
    <limit lower="-3.0892" upper="2.6704" effort="25" velocity="37" />
  </joint>
  <link name="left_shoulder_roll_link">
    <inertial>
      <origin xyz="-0.000227 0.00727 -0.063243" rpy="0 0 0" />
      <mass value="0.643" />
      <inertia ixx="0.0006177" ixy="-1E-06" ixz="8.7E-06" iyy="0.0006912" iyz="-5.3E-06" izz="0.0003894" />
    </inertial>
    <visual>
      <origin xyz="0 0 0" rpy="0 0 0" />
      <geometry>
        <mesh filename="../mesh/G1/left_shoulder_roll_link.stl" />
      </geometry>
      <material name="white">
        <color rgba="0.7 0.7 0.7 1" />
      </material>
    </visual>
    <collision>
      <origin xyz="-0.004 0.006 -0.053" rpy="0 0 0" />
      <geometry>
        <cylinder radius="0.03" length="0.03" />
      </geometry>
    </collision>
  </link>
  <joint name="left_shoulder_roll_joint" type="revolute">
    <origin xyz="0 0.038 -0.013831" rpy="-0.27925 0 0" />
    <parent link="left_shoulder_pitch_link" />
    <child link="left_shoulder_roll_link" />
    <axis xyz="1 0 0" />
    <limit lower="-1.5882" upper="2.2515" effort="25" velocity="37" />
  </joint>
  <link name="left_shoulder_yaw_link">
    <inertial>
      <origin xyz="0.010773 -0.002949 -0.072009" rpy="0 0 0" />
      <mass value="0.734" />
      <inertia ixx="0.0009988" ixy="7.9E-06" ixz="0.0001412" iyy="0.0010605" iyz="-2.86E-05" izz="0.0004354" />
    </inertial>
    <visual>
      <origin xyz="0 0 0" rpy="0 0 0" />
      <geometry>
        <mesh filename="../mesh/G1/left_shoulder_yaw_link.stl" />
      </geometry>
      <material name="white">
        <color rgba="0.7 0.7 0.7 1" />
      </material>
    </visual>
    <collision>
      <origin xyz="0 0 0" rpy="0 0 0" />
      <geometry>
        <mesh filename="../mesh/G1/left_shoulder_yaw_link.stl" />
      </geometry>
    </collision>
  </link>
  <joint name="left_shoulder_yaw_joint" type="revolute">
    <origin xyz="0 0.00624 -0.1032" rpy="0 0 0" />
    <parent link="left_shoulder_roll_link" />
    <child link="left_shoulder_yaw_link" />
    <axis xyz="0 0 1" />
    <limit lower="-2.618" upper="2.618" effort="25" velocity="37" />
  </joint>
  <link name="left_elbow_link">
    <inertial>
      <origin xyz="0.064956 0.004454 -0.010062" rpy="0 0 0" />
      <mass value="0.6" />
      <inertia ixx="0.0002891" ixy="6.53E-05" ixz="1.72E-05" iyy="0.0004152" iyz="-5.6E-06" izz="0.0004197" />
    </inertial>
    <visual>
      <origin xyz="0 0 0" rpy="0 0 0" />
      <geometry>
        <mesh filename="../mesh/G1/left_elbow_link.stl" />
      </geometry>
      <material name="white">
        <color rgba="0.7 0.7 0.7 1" />
      </material>
    </visual>
    <collision>
      <origin xyz="0 0 0" rpy="0 0 0" />
      <geometry>
        <mesh filename="../mesh/G1/left_elbow_link.stl" />
      </geometry>
    </collision>
  </link>
  <joint name="left_elbow_joint" type="revolute">
    <origin xyz="0.015783 0 -0.080518" rpy="0 0 0" />
    <parent link="left_shoulder_yaw_link" />
    <child link="left_elbow_link" />
    <axis xyz="0 1 0" />
    <limit lower="-1.0472" upper="2.0944" effort="25" velocity="37" />
  </joint>
  <joint name="left_wrist_roll_joint" type="revolute">
    <origin xyz="0.100 0.00188791 -0.010" rpy="0 0 0" />
    <axis xyz="1 0 0" />
    <parent link="left_elbow_link" />
    <child link="left_wrist_roll_link" />
    <limit effort="25" velocity="37" lower="-1.972222054" upper="1.972222054" />
  </joint>
  <link name="left_wrist_roll_link">
    <inertial>
      <origin xyz="0.01713944778 0.00053759094 0.00000048864" rpy="0 0 0" />
      <mass value="0.08544498" />
      <inertia ixx="0.00004821544023" ixy="-0.00000424511021" ixz="0.00000000510599" iyy="0.00003722899093" iyz="-0.00000000123525" izz="0.00005482106541" />
    </inertial>
    <visual>
      <origin xyz="0 0 0" rpy="0 0 0" />
      <geometry>
        <mesh filename="../mesh/G1/left_wrist_roll_link.stl" />
      </geometry>
      <material name="white">
        <color rgba="0.7 0.7 0.7 1" />
      </material>
    </visual>
    <collision>
      <origin xyz="0 0 0" rpy="0 0 0" />
      <geometry>
        <mesh filename="../mesh/G1/left_wrist_roll_link.stl" />
      </geometry>
    </collision>
  </link>
  <joint name="left_wrist_pitch_joint" type="revolute">
    <origin xyz="0.038 0 0" rpy="0 0 0" />
    <axis xyz="0 1 0" />
    <parent link="left_wrist_roll_link" />
    <child link="left_wrist_pitch_link" />
    <limit effort="5" velocity="22" lower="-1.614429558" upper="1.614429558" />
  </joint>
  <link name="left_wrist_pitch_link">
    <inertial>
      <origin xyz="0.02299989837 -0.00111685314 -0.00111658096" rpy="0 0 0" />
      <mass value="0.48404956" />
      <inertia ixx="0.00016579646273" ixy="-0.00001231206746" ixz="0.00001231699194" iyy="0.00042954057410" iyz="0.00000081417712" izz="0.00042953697654" />
    </inertial>
    <visual>
      <origin xyz="0 0 0" rpy="0 0 0" />
      <geometry>
        <mesh filename="../mesh/G1/left_wrist_pitch_link.stl" />
      </geometry>
      <material name="white">
        <color rgba="0.7 0.7 0.7 1" />
      </material>
    </visual>
    <collision>
      <origin xyz="0 0 0" rpy="0 0 0" />
      <geometry>
        <mesh filename="../mesh/G1/left_wrist_pitch_link.stl" />
      </geometry>
    </collision>
  </link>
  <joint name="left_wrist_yaw_joint" type="revolute">
    <origin xyz="0.046 0 0" rpy="0 0 0" />
    <axis xyz="0 0 1" />
    <parent link="left_wrist_pitch_link" />
    <child link="left_wrist_yaw_link" />
    <limit effort="5" velocity="22" lower="-1.614429558" upper="1.614429558" />
  </joint>
  <link name="left_wrist_yaw_link">
    <inertial>
      <origin xyz="0.02200381568 0.00049485096 0.00053861123" rpy="0 0 0" />
      <mass value="0.08457647" />
      <inertia ixx="0.00004929128828" ixy="-0.00000045735494" ixz="0.00000445867591" iyy="0.00005973338134" iyz="0.00000043217198" izz="0.00003928083826" />
    </inertial>
    <visual>
      <origin xyz="0 0 0" rpy="0 0 0" />
      <geometry>
        <mesh filename="../mesh/G1/left_wrist_yaw_link.stl" />
      </geometry>
      <material name="white">
        <color rgba="0.7 0.7 0.7 1" />
      </material>
    </visual>
    <collision>
      <origin xyz="0 0 0" rpy="0 0 0" />
      <geometry>
        <mesh filename="../mesh/G1/left_wrist_yaw_link.stl" />
      </geometry>
    </collision>
  </link>
  <joint name="left_hand_palm_joint" type="fixed" dont_collapse="true">
    <origin xyz="0.0415 0.003 0" rpy="0 0 0" />
    <parent link="left_wrist_yaw_link" />
    <child link="left_rubber_hand" />
  </joint>
  <link name="left_rubber_hand">
    <inertial>
      <origin xyz="0.05361310808 -0.00295905240 0.00215413091" rpy="0 0 0" />
      <mass value="0.170" />
      <inertia ixx="0.00010099485234748" ixy="0.00003618590790516" ixz="-0.00000074301518642" iyy="0.00028135871571621" iyz="0.00000330189743286" izz="0.00021894770413514" />
    </inertial>
    <visual>
      <origin xyz="0 0 0" rpy="0 0 0" />
      <geometry>
        <mesh filename="../mesh/G1/left_rubber_hand.stl" />
      </geometry>
      <material name="white">
        <color rgba="0.7 0.7 0.7 1" />
      </material>
    </visual>
  </link>
  <link name="right_shoulder_pitch_link">
    <inertial>
      <origin xyz="0 -0.035892 -0.011628" rpy="0 0 0" />
      <mass value="0.718" />
      <inertia ixx="0.0004291" ixy="9.2E-06" ixz="6.4E-06" iyy="0.000453" iyz="-2.26E-05" izz="0.000423" />
    </inertial>
    <visual>
      <origin xyz="0 0 0" rpy="0 0 0" />
      <geometry>
        <mesh filename="../mesh/G1/right_shoulder_pitch_link.stl" />
      </geometry>
      <material name="white">
        <color rgba="0.7 0.7 0.7 1" />
      </material>
    </visual>
    <collision>
      <origin xyz="0 -0.04 -0.01" rpy="0 1.5707963267948966 0" />
      <geometry>
        <cylinder radius="0.03" length="0.05" />
      </geometry>
    </collision>
  </link>
  <joint name="right_shoulder_pitch_joint" type="revolute">
    <origin xyz="0.0039563 -0.10021 0.23778" rpy="-0.27931 5.4949E-05 0.00019159" />
    <parent link="torso_link" />
    <child link="right_shoulder_pitch_link" />
    <axis xyz="0 1 0" />
    <limit lower="-3.0892" upper="2.6704" effort="25" velocity="37" />
  </joint>
  <link name="right_shoulder_roll_link">
    <inertial>
      <origin xyz="-0.000227 -0.00727 -0.063243" rpy="0 0 0" />
      <mass value="0.643" />
      <inertia ixx="0.0006177" ixy="1E-06" ixz="8.7E-06" iyy="0.0006912" iyz="5.3E-06" izz="0.0003894" />
    </inertial>
    <visual>
      <origin xyz="0 0 0" rpy="0 0 0" />
      <geometry>
        <mesh filename="../mesh/G1/right_shoulder_roll_link.stl" />
      </geometry>
      <material name="white">
        <color rgba="0.7 0.7 0.7 1" />
      </material>
    </visual>
    <collision>
      <origin xyz="-0.004 -0.006 -0.053" rpy="0 0 0" />
      <geometry>
        <cylinder radius="0.03" length="0.03" />
      </geometry>
    </collision>
  </link>
  <joint name="right_shoulder_roll_joint" type="revolute">
    <origin xyz="0 -0.038 -0.013831" rpy="0.27925 0 0" />
    <parent link="right_shoulder_pitch_link" />
    <child link="right_shoulder_roll_link" />
    <axis xyz="1 0 0" />
    <limit lower="-2.2515" upper="1.5882" effort="25" velocity="37" />
  </joint>
  <link name="right_shoulder_yaw_link">
    <inertial>
      <origin xyz="0.010773 0.002949 -0.072009" rpy="0 0 0" />
      <mass value="0.734" />
      <inertia ixx="0.0009988" ixy="-7.9E-06" ixz="0.0001412" iyy="0.0010605" iyz="2.86E-05" izz="0.0004354" />
    </inertial>
    <visual>
      <origin xyz="0 0 0" rpy="0 0 0" />
      <geometry>
        <mesh filename="../mesh/G1/right_shoulder_yaw_link.stl" />
      </geometry>
      <material name="white">
        <color rgba="0.7 0.7 0.7 1" />
      </material>
    </visual>
    <collision>
      <origin xyz="0 0 0" rpy="0 0 0" />
      <geometry>
        <mesh filename="../mesh/G1/right_shoulder_yaw_link.stl" />
      </geometry>
    </collision>
  </link>
  <joint name="right_shoulder_yaw_joint" type="revolute">
    <origin xyz="0 -0.00624 -0.1032" rpy="0 0 0" />
    <parent link="right_shoulder_roll_link" />
    <child link="right_shoulder_yaw_link" />
    <axis xyz="0 0 1" />
    <limit lower="-2.618" upper="2.618" effort="25" velocity="37" />
  </joint>
  <link name="right_elbow_link">
    <inertial>
      <origin xyz="0.064956 -0.004454 -0.010062" rpy="0 0 0" />
      <mass value="0.6" />
      <inertia ixx="0.0002891" ixy="-6.53E-05" ixz="1.72E-05" iyy="0.0004152" iyz="5.6E-06" izz="0.0004197" />
    </inertial>
    <visual>
      <origin xyz="0 0 0" rpy="0 0 0" />
      <geometry>
        <mesh filename="../mesh/G1/right_elbow_link.stl" />
      </geometry>
      <material name="white">
        <color rgba="0.7 0.7 0.7 1" />
      </material>
    </visual>
    <collision>
      <origin xyz="0 0 0" rpy="0 0 0" />
      <geometry>
        <mesh filename="../mesh/G1/right_elbow_link.stl" />
      </geometry>
    </collision>
  </link>
  <joint name="right_elbow_joint" type="revolute">
    <origin xyz="0.015783 0 -0.080518" rpy="0 0 0" />
    <parent link="right_shoulder_yaw_link" />
    <child link="right_elbow_link" />
    <axis xyz="0 1 0" />
    <limit lower="-1.0472" upper="2.0944" effort="25" velocity="37" />
  </joint>
  <joint name="right_wrist_roll_joint" type="revolute">
    <origin xyz="0.100 -0.00188791 -0.010" rpy="0 0 0" />
    <axis xyz="1 0 0" />
    <parent link="right_elbow_link" />
    <child link="right_wrist_roll_link" />
    <limit effort="25" velocity="37" lower="-1.972222054" upper="1.972222054" />
  </joint>
  <link name="right_wrist_roll_link">
    <inertial>
      <origin xyz="0.01713944778 -0.00053759094 0.00000048864" rpy="0 0 0" />
      <mass value="0.08544498" />
      <inertia ixx="0.00004821544023" ixy="0.00000424511021" ixz="0.00000000510599" iyy="0.00003722899093" iyz="0.00000000123525" izz="0.00005482106541" />
    </inertial>
    <visual>
      <origin xyz="0 0 0" rpy="0 0 0" />
      <geometry>
        <mesh filename="../mesh/G1/right_wrist_roll_link.stl" />
      </geometry>
      <material name="white">
        <color rgba="0.7 0.7 0.7 1" />
      </material>
    </visual>
    <collision>
      <origin xyz="0 0 0" rpy="0 0 0" />
      <geometry>
        <mesh filename="../mesh/G1/right_wrist_roll_link.stl" />
      </geometry>
    </collision>
  </link>
  <joint name="right_wrist_pitch_joint" type="revolute">
    <origin xyz="0.038 0 0" rpy="0 0 0" />
    <axis xyz="0 1 0" />
    <parent link="right_wrist_roll_link" />
    <child link="right_wrist_pitch_link" />
    <limit effort="5" velocity="22" lower="-1.614429558" upper="1.614429558" />
  </joint>
  <link name="right_wrist_pitch_link">
    <inertial>
      <origin xyz="0.02299989837 0.00111685314 -0.00111658096" rpy="0 0 0" />
      <mass value="0.48404956" />
      <inertia ixx="0.00016579646273" ixy="0.00001231206746" ixz="0.00001231699194" iyy="0.00042954057410" iyz="-0.00000081417712" izz="0.00042953697654" />
    </inertial>
    <visual>
      <origin xyz="0 0 0" rpy="0 0 0" />
      <geometry>
        <mesh filename="../mesh/G1/right_wrist_pitch_link.stl" />
      </geometry>
      <material name="white">
        <color rgba="0.7 0.7 0.7 1" />
      </material>
    </visual>
    <collision>
      <origin xyz="0 0 0" rpy="0 0 0" />
      <geometry>
        <mesh filename="../mesh/G1/right_wrist_pitch_link.stl" />
      </geometry>
    </collision>
  </link>
  <joint name="right_wrist_yaw_joint" type="revolute">
    <origin xyz="0.046 0 0" rpy="0 0 0" />
    <axis xyz="0 0 1" />
    <parent link="right_wrist_pitch_link" />
    <child link="right_wrist_yaw_link" />
    <limit effort="5" velocity="22" lower="-1.614429558" upper="1.614429558" />
  </joint>
  <link name="right_wrist_yaw_link">
    <inertial>
      <origin xyz="0.02200381568 -0.00049485096 0.00053861123" rpy="0 0 0" />
      <mass value="0.08457647" />
      <inertia ixx="0.00004929128828" ixy="0.00000045735494" ixz="0.00000445867591" iyy="0.00005973338134" iyz="-0.00000043217198" izz="0.00003928083826" />
    </inertial>
    <visual>
      <origin xyz="0 0 0" rpy="0 0 0" />
      <geometry>
        <mesh filename="../mesh/G1/right_wrist_yaw_link.stl" />
      </geometry>
      <material name="white">
        <color rgba="0.7 0.7 0.7 1" />
      </material>
    </visual>
    <collision>
      <origin xyz="0 0 0" rpy="0 0 0" />
      <geometry>
        <mesh filename="../mesh/G1/right_wrist_yaw_link.stl" />
      </geometry>
    </collision>
  </link>
  <joint name="right_hand_palm_joint" type="fixed" dont_collapse="true">
    <origin xyz="0.0415 -0.003 0" rpy="0 0 0" />
    <parent link="right_wrist_yaw_link" />
    <child link="right_rubber_hand" />
  </joint>
  <link name="right_rubber_hand">
    <inertial>
      <origin xyz="0.05361310808 0.00295905240 0.00215413091" rpy="0 0 0" />
      <mass value="0.170" />
      <inertia ixx="0.00010099485234748" ixy="-0.00003618590790516" ixz="-0.00000074301518642" iyy="0.00028135871571621" iyz="-0.00000330189743286" izz="0.00021894770413514" />
    </inertial>
    <visual>
      <origin xyz="0 0 0" rpy="0 0 0" />
      <geometry>
        <mesh filename="../mesh/G1/right_rubber_hand.stl" />
      </geometry>
      <material name="white">
        <color rgba="0.7 0.7 0.7 1" />
      </material>
    </visual>
  </link>
  <link name="head">
    <visual>
      <geometry>
        <sphere radius="0.0001" />
      </geometry>
    </visual>
  </link>
  <joint name="head" type="fixed" dont_collapse="true">
    <parent link="pelvis" />
    <child link="head" />
    <origin xyz="0 0 0.4" rpy="0 0 0" />
  </joint>
  <link name="left_ankle_roll_link_sensor_0">
    <inertial>
      <origin xyz="0 0 0" rpy="0 0 0" />
      <mass value="0.001" />
      <inertia ixx="1e-7" ixy="0" ixz="0" iyy="1e-7" iyz="0" izz="1e-7" />
    </inertial>
    <visual>
      <origin xyz="0 0 0" rpy="0 0 0" />
      <geometry>
        <box size="0.01 0.01 0.004" />
      </geometry>
      <material name="blue">
        <color rgba="0 0 1 1" />
      </material>
    </visual>
    <collision>
      <origin xyz="0 0 0" rpy="0 0 0" />
      <geometry>
        <box size="0.01 0.01 0.004" />
      </geometry>
    </collision>
  </link>
  <joint name="left_ankle_roll_link_sensor_0_joint" type="fixed">
    <parent link="left_ankle_roll_link" />
    <child link="left_ankle_roll_link_sensor_0" />
    <origin xyz="-0.05147892742460647 -0.020779196468829614 -0.035409145057201385" rpy="0 0 0" />
  </joint>
  <link name="left_ankle_roll_link_sensor_1">
    <inertial>
      <origin xyz="0 0 0" rpy="0 0 0" />
      <mass value="0.001" />
      <inertia ixx="1e-7" ixy="0" ixz="0" iyy="1e-7" iyz="0" izz="1e-7" />
    </inertial>
    <visual>
      <origin xyz="0 0 0" rpy="0 0 0" />
      <geometry>
        <box size="0.01 0.01 0.004" />
      </geometry>
      <material name="blue">
        <color rgba="0 0 1 1" />
      </material>
    </visual>
    <collision>
      <origin xyz="0 0 0" rpy="0 0 0" />
      <geometry>
        <box size="0.01 0.01 0.004" />
      </geometry>
    </collision>
  </link>
  <joint name="left_ankle_roll_link_sensor_1_joint" type="fixed">
    <parent link="left_ankle_roll_link" />
    <child link="left_ankle_roll_link_sensor_1" />
    <origin xyz="-0.030403543373492832 -0.027194422708087983 -0.035409145057201385" rpy="0 0 0" />
  </joint>
  <link name="left_ankle_roll_link_sensor_2">
    <inertial>
      <origin xyz="0 0 0" rpy="0 0 0" />
      <mass value="0.001" />
      <inertia ixx="1e-7" ixy="0" ixz="0" iyy="1e-7" iyz="0" izz="1e-7" />
    </inertial>
    <visual>
      <origin xyz="0 0 0" rpy="0 0 0" />
      <geometry>
        <box size="0.01 0.01 0.004" />
      </geometry>
      <material name="blue">
        <color rgba="0 0 1 1" />
      </material>
    </visual>
    <collision>
      <origin xyz="0 0 0" rpy="0 0 0" />
      <geometry>
        <box size="0.01 0.01 0.004" />
      </geometry>
    </collision>
  </link>
  <joint name="left_ankle_roll_link_sensor_2_joint" type="fixed">
    <parent link="left_ankle_roll_link" />
    <child link="left_ankle_roll_link_sensor_2" />
    <origin xyz="0.004008545243229822 -0.027817265905054577 -0.035409145057201385" rpy="0 0 0" />
  </joint>
  <link name="left_ankle_roll_link_sensor_3">
    <inertial>
      <origin xyz="0 0 0" rpy="0 0 0" />
      <mass value="0.001" />
      <inertia ixx="1e-7" ixy="0" ixz="0" iyy="1e-7" iyz="0" izz="1e-7" />
    </inertial>
    <visual>
      <origin xyz="0 0 0" rpy="0 0 0" />
      <geometry>
        <box size="0.01 0.01 0.004" />
      </geometry>
      <material name="blue">
        <color rgba="0 0 1 1" />
      </material>
    </visual>
    <collision>
      <origin xyz="0 0 0" rpy="0 0 0" />
      <geometry>
        <box size="0.01 0.01 0.004" />
      </geometry>
    </collision>
  </link>
  <joint name="left_ankle_roll_link_sensor_3_joint" type="fixed">
    <parent link="left_ankle_roll_link" />
    <child link="left_ankle_roll_link_sensor_3" />
    <origin xyz="0.03728386552887426 -0.02872146074463769 -0.035409145057201385" rpy="0 0 0" />
  </joint>
  <link name="left_ankle_roll_link_sensor_4">
    <inertial>
      <origin xyz="0 0 0" rpy="0 0 0" />
      <mass value="0.001" />
      <inertia ixx="1e-7" ixy="0" ixz="0" iyy="1e-7" iyz="0" izz="1e-7" />
    </inertial>
    <visual>
      <origin xyz="0 0 0" rpy="0 0 0" />
      <geometry>
        <box size="0.01 0.01 0.004" />
      </geometry>
      <material name="blue">
        <color rgba="0 0 1 1" />
      </material>
    </visual>
    <collision>
      <origin xyz="0 0 0" rpy="0 0 0" />
      <geometry>
        <box size="0.01 0.01 0.004" />
      </geometry>
    </collision>
  </link>
  <joint name="left_ankle_roll_link_sensor_4_joint" type="fixed">
    <parent link="left_ankle_roll_link" />
    <child link="left_ankle_roll_link_sensor_4" />
    <origin xyz="0.07093099047943345 -0.02619078630258939 -0.035409145057201385" rpy="0 0 0" />
  </joint>
  <link name="left_ankle_roll_link_sensor_5">
    <inertial>
      <origin xyz="0 0 0" rpy="0 0 0" />
      <mass value="0.001" />
      <inertia ixx="1e-7" ixy="0" ixz="0" iyy="1e-7" iyz="0" izz="1e-7" />
    </inertial>
    <visual>
      <origin xyz="0 0 0" rpy="0 0 0" />
      <geometry>
        <box size="0.01 0.01 0.004" />
      </geometry>
      <material name="blue">
        <color rgba="0 0 1 1" />
      </material>
    </visual>
    <collision>
      <origin xyz="0 0 0" rpy="0 0 0" />
      <geometry>
        <box size="0.01 0.01 0.004" />
      </geometry>
    </collision>
  </link>
  <joint name="left_ankle_roll_link_sensor_5_joint" type="fixed">
    <parent link="left_ankle_roll_link" />
    <child link="left_ankle_roll_link_sensor_5" />
    <origin xyz="0.10503671665431294 -0.025746526307404365 -0.035409145057201385" rpy="0 0 0" />
  </joint>
  <link name="left_ankle_roll_link_sensor_6">
    <inertial>
      <origin xyz="0 0 0" rpy="0 0 0" />
      <mass value="0.001" />
      <inertia ixx="1e-7" ixy="0" ixz="0" iyy="1e-7" iyz="0" izz="1e-7" />
    </inertial>
    <visual>
      <origin xyz="0 0 0" rpy="0 0 0" />
      <geometry>
        <box size="0.01 0.01 0.004" />
      </geometry>
      <material name="blue">
        <color rgba="0 0 1 1" />
      </material>
    </visual>
    <collision>
      <origin xyz="0 0 0" rpy="0 0 0" />
      <geometry>
        <box size="0.01 0.01 0.004" />
      </geometry>
    </collision>
  </link>
  <joint name="left_ankle_roll_link_sensor_6_joint" type="fixed">
    <parent link="left_ankle_roll_link" />
    <child link="left_ankle_roll_link_sensor_6" />
    <origin xyz="0.13085034489631653 -0.023347636684775352 -0.035409145057201385" rpy="0 0 0" />
  </joint>
  <link name="left_ankle_roll_link_sensor_7">
    <inertial>
      <origin xyz="0 0 0" rpy="0 0 0" />
      <mass value="0.001" />
      <inertia ixx="1e-7" ixy="0" ixz="0" iyy="1e-7" iyz="0" izz="1e-7" />
    </inertial>
    <visual>
      <origin xyz="0 0 0" rpy="0 0 0" />
      <geometry>
        <box size="0.01 0.01 0.004" />
      </geometry>
      <material name="blue">
        <color rgba="0 0 1 1" />
      </material>
    </visual>
    <collision>
      <origin xyz="0 0 0" rpy="0 0 0" />
      <geometry>
        <box size="0.01 0.01 0.004" />
      </geometry>
    </collision>
  </link>
  <joint name="left_ankle_roll_link_sensor_7_joint" type="fixed">
    <parent link="left_ankle_roll_link" />
    <child link="left_ankle_roll_link_sensor_7" />
    <origin xyz="-0.054654310640277905 -0.016594955381014194 -0.035409145057201385" rpy="0 0 0" />
  </joint>
  <link name="left_ankle_roll_link_sensor_8">
    <inertial>
      <origin xyz="0 0 0" rpy="0 0 0" />
      <mass value="0.001" />
      <inertia ixx="1e-7" ixy="0" ixz="0" iyy="1e-7" iyz="0" izz="1e-7" />
    </inertial>
    <visual>
      <origin xyz="0 0 0" rpy="0 0 0" />
      <geometry>
        <box size="0.01 0.01 0.004" />
      </geometry>
      <material name="blue">
        <color rgba="0 0 1 1" />
      </material>
    </visual>
    <collision>
      <origin xyz="0 0 0" rpy="0 0 0" />
      <geometry>
        <box size="0.01 0.01 0.004" />
      </geometry>
    </collision>
  </link>
  <joint name="left_ankle_roll_link_sensor_8_joint" type="fixed">
    <parent link="left_ankle_roll_link" />
    <child link="left_ankle_roll_link_sensor_8" />
    <origin xyz="-0.031315424305345486 -0.026428060127047254 -0.035409145057201385" rpy="0 0 0" />
  </joint>
  <link name="left_ankle_roll_link_sensor_9">
    <inertial>
      <origin xyz="0 0 0" rpy="0 0 0" />
      <mass value="0.001" />
      <inertia ixx="1e-7" ixy="0" ixz="0" iyy="1e-7" iyz="0" izz="1e-7" />
    </inertial>
    <visual>
      <origin xyz="0 0 0" rpy="0 0 0" />
      <geometry>
        <box size="0.01 0.01 0.004" />
      </geometry>
      <material name="blue">
        <color rgba="0 0 1 1" />
      </material>
    </visual>
    <collision>
      <origin xyz="0 0 0" rpy="0 0 0" />
      <geometry>
        <box size="0.01 0.01 0.004" />
      </geometry>
    </collision>
  </link>
  <joint name="left_ankle_roll_link_sensor_9_joint" type="fixed">
    <parent link="left_ankle_roll_link" />
    <child link="left_ankle_roll_link_sensor_9" />
    <origin xyz="0.0035820337917938823 -0.024652038169573665 -0.035409145057201385" rpy="0 0 0" />
  </joint>
  <link name="left_ankle_roll_link_sensor_10">
    <inertial>
      <origin xyz="0 0 0" rpy="0 0 0" />
      <mass value="0.001" />
      <inertia ixx="1e-7" ixy="0" ixz="0" iyy="1e-7" iyz="0" izz="1e-7" />
    </inertial>
    <visual>
      <origin xyz="0 0 0" rpy="0 0 0" />
      <geometry>
        <box size="0.01 0.01 0.004" />
      </geometry>
      <material name="blue">
        <color rgba="0 0 1 1" />
      </material>
    </visual>
    <collision>
      <origin xyz="0 0 0" rpy="0 0 0" />
      <geometry>
        <box size="0.01 0.01 0.004" />
      </geometry>
    </collision>
  </link>
  <joint name="left_ankle_roll_link_sensor_10_joint" type="fixed">
    <parent link="left_ankle_roll_link" />
    <child link="left_ankle_roll_link_sensor_10" />
    <origin xyz="0.03815935789983044 -0.024326121316740106 -0.035409145057201385" rpy="0 0 0" />
  </joint>
  <link name="left_ankle_roll_link_sensor_11">
    <inertial>
      <origin xyz="0 0 0" rpy="0 0 0" />
      <mass value="0.001" />
      <inertia ixx="1e-7" ixy="0" ixz="0" iyy="1e-7" iyz="0" izz="1e-7" />
    </inertial>
    <visual>
      <origin xyz="0 0 0" rpy="0 0 0" />
      <geometry>
        <box size="0.01 0.01 0.004" />
      </geometry>
      <material name="blue">
        <color rgba="0 0 1 1" />
      </material>
    </visual>
    <collision>
      <origin xyz="0 0 0" rpy="0 0 0" />
      <geometry>
        <box size="0.01 0.01 0.004" />
      </geometry>
    </collision>
  </link>
  <joint name="left_ankle_roll_link_sensor_11_joint" type="fixed">
    <parent link="left_ankle_roll_link" />
    <child link="left_ankle_roll_link_sensor_11" />
    <origin xyz="0.07185805629856089 -0.02284244607846517 -0.035409145057201385" rpy="0 0 0" />
  </joint>
  <link name="left_ankle_roll_link_sensor_12">
    <inertial>
      <origin xyz="0 0 0" rpy="0 0 0" />
      <mass value="0.001" />
      <inertia ixx="1e-7" ixy="0" ixz="0" iyy="1e-7" iyz="0" izz="1e-7" />
    </inertial>
    <visual>
      <origin xyz="0 0 0" rpy="0 0 0" />
      <geometry>
        <box size="0.01 0.01 0.004" />
      </geometry>
      <material name="blue">
        <color rgba="0 0 1 1" />
      </material>
    </visual>
    <collision>
      <origin xyz="0 0 0" rpy="0 0 0" />
      <geometry>
        <box size="0.01 0.01 0.004" />
      </geometry>
    </collision>
  </link>
  <joint name="left_ankle_roll_link_sensor_12_joint" type="fixed">
    <parent link="left_ankle_roll_link" />
    <child link="left_ankle_roll_link_sensor_12" />
    <origin xyz="0.10420953773494139 -0.020340784162721975 -0.035409145057201385" rpy="0 0 0" />
  </joint>
  <link name="left_ankle_roll_link_sensor_13">
    <inertial>
      <origin xyz="0 0 0" rpy="0 0 0" />
      <mass value="0.001" />
      <inertia ixx="1e-7" ixy="0" ixz="0" iyy="1e-7" iyz="0" izz="1e-7" />
    </inertial>
    <visual>
      <origin xyz="0 0 0" rpy="0 0 0" />
      <geometry>
        <box size="0.01 0.01 0.004" />
      </geometry>
      <material name="blue">
        <color rgba="0 0 1 1" />
      </material>
    </visual>
    <collision>
      <origin xyz="0 0 0" rpy="0 0 0" />
      <geometry>
        <box size="0.01 0.01 0.004" />
      </geometry>
    </collision>
  </link>
  <joint name="left_ankle_roll_link_sensor_13_joint" type="fixed">
    <parent link="left_ankle_roll_link" />
    <child link="left_ankle_roll_link_sensor_13" />
    <origin xyz="0.13351999559828798 -0.017105046694074273 -0.035409145057201385" rpy="0 0 0" />
  </joint>
  <link name="left_ankle_roll_link_sensor_14">
    <inertial>
      <origin xyz="0 0 0" rpy="0 0 0" />
      <mass value="0.001" />
      <inertia ixx="1e-7" ixy="0" ixz="0" iyy="1e-7" iyz="0" izz="1e-7" />
    </inertial>
    <visual>
      <origin xyz="0 0 0" rpy="0 0 0" />
      <geometry>
        <box size="0.01 0.01 0.004" />
      </geometry>
      <material name="blue">
        <color rgba="0 0 1 1" />
      </material>
    </visual>
    <collision>
      <origin xyz="0 0 0" rpy="0 0 0" />
      <geometry>
        <box size="0.01 0.01 0.004" />
      </geometry>
    </collision>
  </link>
  <joint name="left_ankle_roll_link_sensor_14_joint" type="fixed">
    <parent link="left_ankle_roll_link" />
    <child link="left_ankle_roll_link_sensor_14" />
    <origin xyz="-0.05795339814852556 -0.01035503404033698 -0.035409145057201385" rpy="0 0 0" />
  </joint>
  <link name="left_ankle_roll_link_sensor_15">
    <inertial>
      <origin xyz="0 0 0" rpy="0 0 0" />
      <mass value="0.001" />
      <inertia ixx="1e-7" ixy="0" ixz="0" iyy="1e-7" iyz="0" izz="1e-7" />
    </inertial>
    <visual>
      <origin xyz="0 0 0" rpy="0 0 0" />
      <geometry>
        <box size="0.01 0.01 0.004" />
      </geometry>
      <material name="blue">
        <color rgba="0 0 1 1" />
      </material>
    </visual>
    <collision>
      <origin xyz="0 0 0" rpy="0 0 0" />
      <geometry>
        <box size="0.01 0.01 0.004" />
      </geometry>
    </collision>
  </link>
  <joint name="left_ankle_roll_link_sensor_15_joint" type="fixed">
    <parent link="left_ankle_roll_link" />
    <child link="left_ankle_roll_link_sensor_15" />
    <origin xyz="-0.026499983852078746 -0.01254755427615068 -0.035409145057201385" rpy="0 0 0" />
  </joint>
  <link name="left_ankle_roll_link_sensor_16">
    <inertial>
      <origin xyz="0 0 0" rpy="0 0 0" />
      <mass value="0.001" />
      <inertia ixx="1e-7" ixy="0" ixz="0" iyy="1e-7" iyz="0" izz="1e-7" />
    </inertial>
    <visual>
      <origin xyz="0 0 0" rpy="0 0 0" />
      <geometry>
        <box size="0.01 0.01 0.004" />
      </geometry>
      <material name="blue">
        <color rgba="0 0 1 1" />
      </material>
    </visual>
    <collision>
      <origin xyz="0 0 0" rpy="0 0 0" />
      <geometry>
        <box size="0.01 0.01 0.004" />
      </geometry>
    </collision>
  </link>
  <joint name="left_ankle_roll_link_sensor_16_joint" type="fixed">
    <parent link="left_ankle_roll_link" />
    <child link="left_ankle_roll_link_sensor_16" />
    <origin xyz="0.003049850150604592 -0.02444328066435545 -0.035409145057201385" rpy="0 0 0" />
  </joint>
  <link name="left_ankle_roll_link_sensor_17">
    <inertial>
      <origin xyz="0 0 0" rpy="0 0 0" />
      <mass value="0.001" />
      <inertia ixx="1e-7" ixy="0" ixz="0" iyy="1e-7" iyz="0" izz="1e-7" />
    </inertial>
    <visual>
      <origin xyz="0 0 0" rpy="0 0 0" />
      <geometry>
        <box size="0.01 0.01 0.004" />
      </geometry>
      <material name="blue">
        <color rgba="0 0 1 1" />
      </material>
    </visual>
    <collision>
      <origin xyz="0 0 0" rpy="0 0 0" />
      <geometry>
        <box size="0.01 0.01 0.004" />
      </geometry>
    </collision>
  </link>
  <joint name="left_ankle_roll_link_sensor_17_joint" type="fixed">
    <parent link="left_ankle_roll_link" />
    <child link="left_ankle_roll_link_sensor_17" />
    <origin xyz="0.040099611243184986 -0.022163588004883588 -0.035409145057201385" rpy="0 0 0" />
  </joint>
  <link name="left_ankle_roll_link_sensor_18">
    <inertial>
      <origin xyz="0 0 0" rpy="0 0 0" />
      <mass value="0.001" />
      <inertia ixx="1e-7" ixy="0" ixz="0" iyy="1e-7" iyz="0" izz="1e-7" />
    </inertial>
    <visual>
      <origin xyz="0 0 0" rpy="0 0 0" />
      <geometry>
        <box size="0.01 0.01 0.004" />
      </geometry>
      <material name="blue">
        <color rgba="0 0 1 1" />
      </material>
    </visual>
    <collision>
      <origin xyz="0 0 0" rpy="0 0 0" />
      <geometry>
        <box size="0.01 0.01 0.004" />
      </geometry>
    </collision>
  </link>
  <joint name="left_ankle_roll_link_sensor_18_joint" type="fixed">
    <parent link="left_ankle_roll_link" />
    <child link="left_ankle_roll_link_sensor_18" />
    <origin xyz="0.07271741908204299 -0.012411505339728467 -0.035409145057201385" rpy="0 0 0" />
  </joint>
  <link name="left_ankle_roll_link_sensor_19">
    <inertial>
      <origin xyz="0 0 0" rpy="0 0 0" />
      <mass value="0.001" />
      <inertia ixx="1e-7" ixy="0" ixz="0" iyy="1e-7" iyz="0" izz="1e-7" />
    </inertial>
    <visual>
      <origin xyz="0 0 0" rpy="0 0 0" />
      <geometry>
        <box size="0.01 0.01 0.004" />
      </geometry>
      <material name="blue">
        <color rgba="0 0 1 1" />
      </material>
    </visual>
    <collision>
      <origin xyz="0 0 0" rpy="0 0 0" />
      <geometry>
        <box size="0.01 0.01 0.004" />
      </geometry>
    </collision>
  </link>
  <joint name="left_ankle_roll_link_sensor_19_joint" type="fixed">
    <parent link="left_ankle_roll_link" />
    <child link="left_ankle_roll_link_sensor_19" />
    <origin xyz="0.10457053378734785 -0.011151025291145214 -0.035409145057201385" rpy="0 0 0" />
  </joint>
  <link name="left_ankle_roll_link_sensor_20">
    <inertial>
      <origin xyz="0 0 0" rpy="0 0 0" />
      <mass value="0.001" />
      <inertia ixx="1e-7" ixy="0" ixz="0" iyy="1e-7" iyz="0" izz="1e-7" />
    </inertial>
    <visual>
      <origin xyz="0 0 0" rpy="0 0 0" />
      <geometry>
        <box size="0.01 0.01 0.004" />
      </geometry>
      <material name="blue">
        <color rgba="0 0 1 1" />
      </material>
    </visual>
    <collision>
      <origin xyz="0 0 0" rpy="0 0 0" />
      <geometry>
        <box size="0.01 0.01 0.004" />
      </geometry>
    </collision>
  </link>
  <joint name="left_ankle_roll_link_sensor_20_joint" type="fixed">
    <parent link="left_ankle_roll_link" />
    <child link="left_ankle_roll_link_sensor_20" />
    <origin xyz="0.13681907467613633 -0.010145958960596384 -0.035409145057201385" rpy="0 0 0" />
  </joint>
  <link name="left_ankle_roll_link_sensor_21">
    <inertial>
      <origin xyz="0 0 0" rpy="0 0 0" />
      <mass value="0.001" />
      <inertia ixx="1e-7" ixy="0" ixz="0" iyy="1e-7" iyz="0" izz="1e-7" />
    </inertial>
    <visual>
      <origin xyz="0 0 0" rpy="0 0 0" />
      <geometry>
        <box size="0.01 0.01 0.004" />
      </geometry>
      <material name="blue">
        <color rgba="0 0 1 1" />
      </material>
    </visual>
    <collision>
      <origin xyz="0 0 0" rpy="0 0 0" />
      <geometry>
        <box size="0.01 0.01 0.004" />
      </geometry>
    </collision>
  </link>
  <joint name="left_ankle_roll_link_sensor_21_joint" type="fixed">
    <parent link="left_ankle_roll_link" />
    <child link="left_ankle_roll_link_sensor_21" />
    <origin xyz="-0.05922419821173717 0.00010739565682747304 -0.035409145057201385" rpy="0 0 0" />
  </joint>
  <link name="left_ankle_roll_link_sensor_22">
    <inertial>
      <origin xyz="0 0 0" rpy="0 0 0" />
      <mass value="0.001" />
      <inertia ixx="1e-7" ixy="0" ixz="0" iyy="1e-7" iyz="0" izz="1e-7" />
    </inertial>
    <visual>
      <origin xyz="0 0 0" rpy="0 0 0" />
      <geometry>
        <box size="0.01 0.01 0.004" />
      </geometry>
      <material name="blue">
        <color rgba="0 0 1 1" />
      </material>
    </visual>
    <collision>
      <origin xyz="0 0 0" rpy="0 0 0" />
      <geometry>
        <box size="0.01 0.01 0.004" />
      </geometry>
    </collision>
  </link>
  <joint name="left_ankle_roll_link_sensor_22_joint" type="fixed">
    <parent link="left_ankle_roll_link" />
    <child link="left_ankle_roll_link_sensor_22" />
    <origin xyz="-0.0262499908001741 -0.005984953963802079 -0.035409145057201385" rpy="0 0 0" />
  </joint>
  <link name="left_ankle_roll_link_sensor_23">
    <inertial>
      <origin xyz="0 0 0" rpy="0 0 0" />
      <mass value="0.001" />
      <inertia ixx="1e-7" ixy="0" ixz="0" iyy="1e-7" iyz="0" izz="1e-7" />
    </inertial>
    <visual>
      <origin xyz="0 0 0" rpy="0 0 0" />
      <geometry>
        <box size="0.01 0.01 0.004" />
      </geometry>
      <material name="blue">
        <color rgba="0 0 1 1" />
      </material>
    </visual>
    <collision>
      <origin xyz="0 0 0" rpy="0 0 0" />
      <geometry>
        <box size="0.01 0.01 0.004" />
      </geometry>
    </collision>
  </link>
  <joint name="left_ankle_roll_link_sensor_23_joint" type="fixed">
    <parent link="left_ankle_roll_link" />
    <child link="left_ankle_roll_link_sensor_23" />
    <origin xyz="0.0035608642155556865 4.9560039428368075e-05 -0.035409145057201385" rpy="0 0 0" />
  </joint>
  <link name="left_ankle_roll_link_sensor_24">
    <inertial>
      <origin xyz="0 0 0" rpy="0 0 0" />
      <mass value="0.001" />
      <inertia ixx="1e-7" ixy="0" ixz="0" iyy="1e-7" iyz="0" izz="1e-7" />
    </inertial>
    <visual>
      <origin xyz="0 0 0" rpy="0 0 0" />
      <geometry>
        <box size="0.01 0.01 0.004" />
      </geometry>
      <material name="blue">
        <color rgba="0 0 1 1" />
      </material>
    </visual>
    <collision>
      <origin xyz="0 0 0" rpy="0 0 0" />
      <geometry>
        <box size="0.01 0.01 0.004" />
      </geometry>
    </collision>
  </link>
  <joint name="left_ankle_roll_link_sensor_24_joint" type="fixed">
    <parent link="left_ankle_roll_link" />
    <child link="left_ankle_roll_link_sensor_24" />
    <origin xyz="0.038261988399023505 4.955734801711267e-05 -0.035409145057201385" rpy="0 0 0" />
  </joint>
  <link name="left_ankle_roll_link_sensor_25">
    <inertial>
      <origin xyz="0 0 0" rpy="0 0 0" />
      <mass value="0.001" />
      <inertia ixx="1e-7" ixy="0" ixz="0" iyy="1e-7" iyz="0" izz="1e-7" />
    </inertial>
    <visual>
      <origin xyz="0 0 0" rpy="0 0 0" />
      <geometry>
        <box size="0.01 0.01 0.004" />
      </geometry>
      <material name="blue">
        <color rgba="0 0 1 1" />
      </material>
    </visual>
    <collision>
      <origin xyz="0 0 0" rpy="0 0 0" />
      <geometry>
        <box size="0.01 0.01 0.004" />
      </geometry>
    </collision>
  </link>
  <joint name="left_ankle_roll_link_sensor_25_joint" type="fixed">
    <parent link="left_ankle_roll_link" />
    <child link="left_ankle_roll_link_sensor_25" />
    <origin xyz="0.07320485979826237 6.860472295831987e-05 -0.035409145057201385" rpy="0 0 0" />
  </joint>
  <link name="left_ankle_roll_link_sensor_26">
    <inertial>
      <origin xyz="0 0 0" rpy="0 0 0" />
      <mass value="0.001" />
      <inertia ixx="1e-7" ixy="0" ixz="0" iyy="1e-7" iyz="0" izz="1e-7" />
    </inertial>
    <visual>
      <origin xyz="0 0 0" rpy="0 0 0" />
      <geometry>
        <box size="0.01 0.01 0.004" />
      </geometry>
      <material name="blue">
        <color rgba="0 0 1 1" />
      </material>
    </visual>
    <collision>
      <origin xyz="0 0 0" rpy="0 0 0" />
      <geometry>
        <box size="0.01 0.01 0.004" />
      </geometry>
    </collision>
  </link>
  <joint name="left_ankle_roll_link_sensor_26_joint" type="fixed">
    <parent link="left_ankle_roll_link" />
    <child link="left_ankle_roll_link_sensor_26" />
    <origin xyz="0.10490943131061078 9.739725267179343e-05 -0.035409145057201385" rpy="0 0 0" />
  </joint>
  <link name="left_ankle_roll_link_sensor_27">
    <inertial>
      <origin xyz="0 0 0" rpy="0 0 0" />
      <mass value="0.001" />
      <inertia ixx="1e-7" ixy="0" ixz="0" iyy="1e-7" iyz="0" izz="1e-7" />
    </inertial>
    <visual>
      <origin xyz="0 0 0" rpy="0 0 0" />
      <geometry>
        <box size="0.01 0.01 0.004" />
      </geometry>
      <material name="blue">
        <color rgba="0 0 1 1" />
      </material>
    </visual>
    <collision>
      <origin xyz="0 0 0" rpy="0 0 0" />
      <geometry>
        <box size="0.01 0.01 0.004" />
      </geometry>
    </collision>
  </link>
  <joint name="left_ankle_roll_link_sensor_27_joint" type="fixed">
    <parent link="left_ankle_roll_link" />
    <child link="left_ankle_roll_link_sensor_27" />
    <origin xyz="0.13776152423912533 6.440720240348226e-05 -0.035409145057201385" rpy="0 0 0" />
  </joint>
  <link name="left_ankle_roll_link_sensor_28">
    <inertial>
      <origin xyz="0 0 0" rpy="0 0 0" />
      <mass value="0.001" />
      <inertia ixx="1e-7" ixy="0" ixz="0" iyy="1e-7" iyz="0" izz="1e-7" />
    </inertial>
    <visual>
      <origin xyz="0 0 0" rpy="0 0 0" />
      <geometry>
        <box size="0.01 0.01 0.004" />
      </geometry>
      <material name="blue">
        <color rgba="0 0 1 1" />
      </material>
    </visual>
    <collision>
      <origin xyz="0 0 0" rpy="0 0 0" />
      <geometry>
        <box size="0.01 0.01 0.004" />
      </geometry>
    </collision>
  </link>
  <joint name="left_ankle_roll_link_sensor_28_joint" type="fixed">
    <parent link="left_ankle_roll_link" />
    <child link="left_ankle_roll_link_sensor_28" />
    <origin xyz="-0.0577644559385961 0.010500682762709296 -0.035409145057201385" rpy="0 0 0" />
  </joint>
  <link name="left_ankle_roll_link_sensor_29">
    <inertial>
      <origin xyz="0 0 0" rpy="0 0 0" />
      <mass value="0.001" />
      <inertia ixx="1e-7" ixy="0" ixz="0" iyy="1e-7" iyz="0" izz="1e-7" />
    </inertial>
    <visual>
      <origin xyz="0 0 0" rpy="0 0 0" />
      <geometry>
        <box size="0.01 0.01 0.004" />
      </geometry>
      <material name="blue">
        <color rgba="0 0 1 1" />
      </material>
    </visual>
    <collision>
      <origin xyz="0 0 0" rpy="0 0 0" />
      <geometry>
        <box size="0.01 0.01 0.004" />
      </geometry>
    </collision>
  </link>
  <joint name="left_ankle_roll_link_sensor_29_joint" type="fixed">
    <parent link="left_ankle_roll_link" />
    <child link="left_ankle_roll_link_sensor_29" />
    <origin xyz="-0.026499990645761893 0.012646676214051654 -0.035409145057201385" rpy="0 0 0" />
  </joint>
  <link name="left_ankle_roll_link_sensor_30">
    <inertial>
      <origin xyz="0 0 0" rpy="0 0 0" />
      <mass value="0.001" />
      <inertia ixx="1e-7" ixy="0" ixz="0" iyy="1e-7" iyz="0" izz="1e-7" />
    </inertial>
    <visual>
      <origin xyz="0 0 0" rpy="0 0 0" />
      <geometry>
        <box size="0.01 0.01 0.004" />
      </geometry>
      <material name="blue">
        <color rgba="0 0 1 1" />
      </material>
    </visual>
    <collision>
      <origin xyz="0 0 0" rpy="0 0 0" />
      <geometry>
        <box size="0.01 0.01 0.004" />
      </geometry>
    </collision>
  </link>
  <joint name="left_ankle_roll_link_sensor_30_joint" type="fixed">
    <parent link="left_ankle_roll_link" />
    <child link="left_ankle_roll_link_sensor_30" />
    <origin xyz="0.0030460716929169556 0.02463821403826059 -0.035409145057201385" rpy="0 0 0" />
  </joint>
  <link name="left_ankle_roll_link_sensor_31">
    <inertial>
      <origin xyz="0 0 0" rpy="0 0 0" />
      <mass value="0.001" />
      <inertia ixx="1e-7" ixy="0" ixz="0" iyy="1e-7" iyz="0" izz="1e-7" />
    </inertial>
    <visual>
      <origin xyz="0 0 0" rpy="0 0 0" />
      <geometry>
        <box size="0.01 0.01 0.004" />
      </geometry>
      <material name="blue">
        <color rgba="0 0 1 1" />
      </material>
    </visual>
    <collision>
      <origin xyz="0 0 0" rpy="0 0 0" />
      <geometry>
        <box size="0.01 0.01 0.004" />
      </geometry>
    </collision>
  </link>
  <joint name="left_ankle_roll_link_sensor_31_joint" type="fixed">
    <parent link="left_ankle_roll_link" />
    <child link="left_ankle_roll_link_sensor_31" />
    <origin xyz="0.04011447790303023 0.022340269001596323 -0.035409145057201385" rpy="0 0 0" />
  </joint>
  <link name="left_ankle_roll_link_sensor_32">
    <inertial>
      <origin xyz="0 0 0" rpy="0 0 0" />
      <mass value="0.001" />
      <inertia ixx="1e-7" ixy="0" ixz="0" iyy="1e-7" iyz="0" izz="1e-7" />
    </inertial>
    <visual>
      <origin xyz="0 0 0" rpy="0 0 0" />
      <geometry>
        <box size="0.01 0.01 0.004" />
      </geometry>
      <material name="blue">
        <color rgba="0 0 1 1" />
      </material>
    </visual>
    <collision>
      <origin xyz="0 0 0" rpy="0 0 0" />
      <geometry>
        <box size="0.01 0.01 0.004" />
      </geometry>
    </collision>
  </link>
  <joint name="left_ankle_roll_link_sensor_32_joint" type="fixed">
    <parent link="left_ankle_roll_link" />
    <child link="left_ankle_roll_link_sensor_32" />
    <origin xyz="0.07272592738178599 0.01251184394373693 -0.035409145057201385" rpy="0 0 0" />
  </joint>
  <link name="left_ankle_roll_link_sensor_33">
    <inertial>
      <origin xyz="0 0 0" rpy="0 0 0" />
      <mass value="0.001" />
      <inertia ixx="1e-7" ixy="0" ixz="0" iyy="1e-7" iyz="0" izz="1e-7" />
    </inertial>
    <visual>
      <origin xyz="0 0 0" rpy="0 0 0" />
      <geometry>
        <box size="0.01 0.01 0.004" />
      </geometry>
      <material name="blue">
        <color rgba="0 0 1 1" />
      </material>
    </visual>
    <collision>
      <origin xyz="0 0 0" rpy="0 0 0" />
      <geometry>
        <box size="0.01 0.01 0.004" />
      </geometry>
    </collision>
  </link>
  <joint name="left_ankle_roll_link_sensor_33_joint" type="fixed">
    <parent link="left_ankle_roll_link" />
    <child link="left_ankle_roll_link_sensor_33" />
    <origin xyz="0.10457482796474882 0.011233994821511363 -0.035409145057201385" rpy="0 0 0" />
  </joint>
  <link name="left_ankle_roll_link_sensor_34">
    <inertial>
      <origin xyz="0 0 0" rpy="0 0 0" />
      <mass value="0.001" />
      <inertia ixx="1e-7" ixy="0" ixz="0" iyy="1e-7" iyz="0" izz="1e-7" />
    </inertial>
    <visual>
      <origin xyz="0 0 0" rpy="0 0 0" />
      <geometry>
        <box size="0.01 0.01 0.004" />
      </geometry>
      <material name="blue">
        <color rgba="0 0 1 1" />
      </material>
    </visual>
    <collision>
      <origin xyz="0 0 0" rpy="0 0 0" />
      <geometry>
        <box size="0.01 0.01 0.004" />
      </geometry>
    </collision>
  </link>
  <joint name="left_ankle_roll_link_sensor_34_joint" type="fixed">
    <parent link="left_ankle_roll_link" />
    <child link="left_ankle_roll_link_sensor_34" />
    <origin xyz="0.13683523690974694 0.010385669331591523 -0.035409145057201385" rpy="0 0 0" />
  </joint>
  <link name="left_ankle_roll_link_sensor_35">
    <inertial>
      <origin xyz="0 0 0" rpy="0 0 0" />
      <mass value="0.001" />
      <inertia ixx="1e-7" ixy="0" ixz="0" iyy="1e-7" iyz="0" izz="1e-7" />
    </inertial>
    <visual>
      <origin xyz="0 0 0" rpy="0 0 0" />
      <geometry>
        <box size="0.01 0.01 0.004" />
      </geometry>
      <material name="blue">
        <color rgba="0 0 1 1" />
      </material>
    </visual>
    <collision>
      <origin xyz="0 0 0" rpy="0 0 0" />
      <geometry>
        <box size="0.01 0.01 0.004" />
      </geometry>
    </collision>
  </link>
  <joint name="left_ankle_roll_link_sensor_35_joint" type="fixed">
    <parent link="left_ankle_roll_link" />
    <child link="left_ankle_roll_link_sensor_35" />
    <origin xyz="-0.05464453070609158 0.016785660576853278 -0.035409145057201385" rpy="0 0 0" />
  </joint>
  <link name="left_ankle_roll_link_sensor_36">
    <inertial>
      <origin xyz="0 0 0" rpy="0 0 0" />
      <mass value="0.001" />
      <inertia ixx="1e-7" ixy="0" ixz="0" iyy="1e-7" iyz="0" izz="1e-7" />
    </inertial>
    <visual>
      <origin xyz="0 0 0" rpy="0 0 0" />
      <geometry>
        <box size="0.01 0.01 0.004" />
      </geometry>
      <material name="blue">
        <color rgba="0 0 1 1" />
      </material>
    </visual>
    <collision>
      <origin xyz="0 0 0" rpy="0 0 0" />
      <geometry>
        <box size="0.01 0.01 0.004" />
      </geometry>
    </collision>
  </link>
  <joint name="left_ankle_roll_link_sensor_36_joint" type="fixed">
    <parent link="left_ankle_roll_link" />
    <child link="left_ankle_roll_link_sensor_36" />
    <origin xyz="-0.03136357704862891 0.02659287456803997 -0.035409145057201385" rpy="0 0 0" />
  </joint>
  <link name="left_ankle_roll_link_sensor_37">
    <inertial>
      <origin xyz="0 0 0" rpy="0 0 0" />
      <mass value="0.001" />
      <inertia ixx="1e-7" ixy="0" ixz="0" iyy="1e-7" iyz="0" izz="1e-7" />
    </inertial>
    <visual>
      <origin xyz="0 0 0" rpy="0 0 0" />
      <geometry>
        <box size="0.01 0.01 0.004" />
      </geometry>
      <material name="blue">
        <color rgba="0 0 1 1" />
      </material>
    </visual>
    <collision>
      <origin xyz="0 0 0" rpy="0 0 0" />
      <geometry>
        <box size="0.01 0.01 0.004" />
      </geometry>
    </collision>
  </link>
  <joint name="left_ankle_roll_link_sensor_37_joint" type="fixed">
    <parent link="left_ankle_roll_link" />
    <child link="left_ankle_roll_link_sensor_37" />
    <origin xyz="0.003577907981471794 0.024846931269105064 -0.035409145057201385" rpy="0 0 0" />
  </joint>
  <link name="left_ankle_roll_link_sensor_38">
    <inertial>
      <origin xyz="0 0 0" rpy="0 0 0" />
      <mass value="0.001" />
      <inertia ixx="1e-7" ixy="0" ixz="0" iyy="1e-7" iyz="0" izz="1e-7" />
    </inertial>
    <visual>
      <origin xyz="0 0 0" rpy="0 0 0" />
      <geometry>
        <box size="0.01 0.01 0.004" />
      </geometry>
      <material name="blue">
        <color rgba="0 0 1 1" />
      </material>
    </visual>
    <collision>
      <origin xyz="0 0 0" rpy="0 0 0" />
      <geometry>
        <box size="0.01 0.01 0.004" />
      </geometry>
    </collision>
  </link>
  <joint name="left_ankle_roll_link_sensor_38_joint" type="fixed">
    <parent link="left_ankle_roll_link" />
    <child link="left_ankle_roll_link_sensor_38" />
    <origin xyz="0.038169697464874586 0.024507736783875342 -0.035409145057201385" rpy="0 0 0" />
  </joint>
  <link name="left_ankle_roll_link_sensor_39">
    <inertial>
      <origin xyz="0 0 0" rpy="0 0 0" />
      <mass value="0.001" />
      <inertia ixx="1e-7" ixy="0" ixz="0" iyy="1e-7" iyz="0" izz="1e-7" />
    </inertial>
    <visual>
      <origin xyz="0 0 0" rpy="0 0 0" />
      <geometry>
        <box size="0.01 0.01 0.004" />
      </geometry>
      <material name="blue">
        <color rgba="0 0 1 1" />
      </material>
    </visual>
    <collision>
      <origin xyz="0 0 0" rpy="0 0 0" />
      <geometry>
        <box size="0.01 0.01 0.004" />
      </geometry>
    </collision>
  </link>
  <joint name="left_ankle_roll_link_sensor_39_joint" type="fixed">
    <parent link="left_ankle_roll_link" />
    <child link="left_ankle_roll_link_sensor_39" />
    <origin xyz="0.07178329263407268 0.02313524455497987 -0.035409145057201385" rpy="0 0 0" />
  </joint>
  <link name="left_ankle_roll_link_sensor_40">
    <inertial>
      <origin xyz="0 0 0" rpy="0 0 0" />
      <mass value="0.001" />
      <inertia ixx="1e-7" ixy="0" ixz="0" iyy="1e-7" iyz="0" izz="1e-7" />
    </inertial>
    <visual>
      <origin xyz="0 0 0" rpy="0 0 0" />
      <geometry>
        <box size="0.01 0.01 0.004" />
      </geometry>
      <material name="blue">
        <color rgba="0 0 1 1" />
      </material>
    </visual>
    <collision>
      <origin xyz="0 0 0" rpy="0 0 0" />
      <geometry>
        <box size="0.01 0.01 0.004" />
      </geometry>
    </collision>
  </link>
  <joint name="left_ankle_roll_link_sensor_40_joint" type="fixed">
    <parent link="left_ankle_roll_link" />
    <child link="left_ankle_roll_link_sensor_40" />
    <origin xyz="0.10443672214540789 0.020417329765378214 -0.035409145057201385" rpy="0 0 0" />
  </joint>
  <link name="left_ankle_roll_link_sensor_41">
    <inertial>
      <origin xyz="0 0 0" rpy="0 0 0" />
      <mass value="0.001" />
      <inertia ixx="1e-7" ixy="0" ixz="0" iyy="1e-7" iyz="0" izz="1e-7" />
    </inertial>
    <visual>
      <origin xyz="0 0 0" rpy="0 0 0" />
      <geometry>
        <box size="0.01 0.01 0.004" />
      </geometry>
      <material name="blue">
        <color rgba="0 0 1 1" />
      </material>
    </visual>
    <collision>
      <origin xyz="0 0 0" rpy="0 0 0" />
      <geometry>
        <box size="0.01 0.01 0.004" />
      </geometry>
    </collision>
  </link>
  <joint name="left_ankle_roll_link_sensor_41_joint" type="fixed">
    <parent link="left_ankle_roll_link" />
    <child link="left_ankle_roll_link_sensor_41" />
    <origin xyz="0.13345379779326969 0.01700604381602516 -0.035409145057201385" rpy="0 0 0" />
  </joint>
  <link name="left_ankle_roll_link_sensor_42">
    <inertial>
      <origin xyz="0 0 0" rpy="0 0 0" />
      <mass value="0.001" />
      <inertia ixx="1e-7" ixy="0" ixz="0" iyy="1e-7" iyz="0" izz="1e-7" />
    </inertial>
    <visual>
      <origin xyz="0 0 0" rpy="0 0 0" />
      <geometry>
        <box size="0.01 0.01 0.004" />
      </geometry>
      <material name="blue">
        <color rgba="0 0 1 1" />
      </material>
    </visual>
    <collision>
      <origin xyz="0 0 0" rpy="0 0 0" />
      <geometry>
        <box size="0.01 0.01 0.004" />
      </geometry>
    </collision>
  </link>
  <joint name="left_ankle_roll_link_sensor_42_joint" type="fixed">
    <parent link="left_ankle_roll_link" />
    <child link="left_ankle_roll_link_sensor_42" />
    <origin xyz="-0.051604356949161476 0.02086911053130067 -0.035409145057201385" rpy="0 0 0" />
  </joint>
  <link name="left_ankle_roll_link_sensor_43">
    <inertial>
      <origin xyz="0 0 0" rpy="0 0 0" />
      <mass value="0.001" />
      <inertia ixx="1e-7" ixy="0" ixz="0" iyy="1e-7" iyz="0" izz="1e-7" />
    </inertial>
    <visual>
      <origin xyz="0 0 0" rpy="0 0 0" />
      <geometry>
        <box size="0.01 0.01 0.004" />
      </geometry>
      <material name="blue">
        <color rgba="0 0 1 1" />
      </material>
    </visual>
    <collision>
      <origin xyz="0 0 0" rpy="0 0 0" />
      <geometry>
        <box size="0.01 0.01 0.004" />
      </geometry>
    </collision>
  </link>
  <joint name="left_ankle_roll_link_sensor_43_joint" type="fixed">
    <parent link="left_ankle_roll_link" />
    <child link="left_ankle_roll_link_sensor_43" />
    <origin xyz="-0.03074988581711633 0.027313085419073634 -0.035409145057201385" rpy="0 0 0" />
  </joint>
  <link name="left_ankle_roll_link_sensor_44">
    <inertial>
      <origin xyz="0 0 0" rpy="0 0 0" />
      <mass value="0.001" />
      <inertia ixx="1e-7" ixy="0" ixz="0" iyy="1e-7" iyz="0" izz="1e-7" />
    </inertial>
    <visual>
      <origin xyz="0 0 0" rpy="0 0 0" />
      <geometry>
        <box size="0.01 0.01 0.004" />
      </geometry>
      <material name="blue">
        <color rgba="0 0 1 1" />
      </material>
    </visual>
    <collision>
      <origin xyz="0 0 0" rpy="0 0 0" />
      <geometry>
        <box size="0.01 0.01 0.004" />
      </geometry>
    </collision>
  </link>
  <joint name="left_ankle_roll_link_sensor_44_joint" type="fixed">
    <parent link="left_ankle_roll_link" />
    <child link="left_ankle_roll_link_sensor_44" />
    <origin xyz="0.004025918527107048 0.02801715079198863 -0.035409145057201385" rpy="0 0 0" />
  </joint>
  <link name="left_ankle_roll_link_sensor_45">
    <inertial>
      <origin xyz="0 0 0" rpy="0 0 0" />
      <mass value="0.001" />
      <inertia ixx="1e-7" ixy="0" ixz="0" iyy="1e-7" iyz="0" izz="1e-7" />
    </inertial>
    <visual>
      <origin xyz="0 0 0" rpy="0 0 0" />
      <geometry>
        <box size="0.01 0.01 0.004" />
      </geometry>
      <material name="blue">
        <color rgba="0 0 1 1" />
      </material>
    </visual>
    <collision>
      <origin xyz="0 0 0" rpy="0 0 0" />
      <geometry>
        <box size="0.01 0.01 0.004" />
      </geometry>
    </collision>
  </link>
  <joint name="left_ankle_roll_link_sensor_45_joint" type="fixed">
    <parent link="left_ankle_roll_link" />
    <child link="left_ankle_roll_link_sensor_45" />
    <origin xyz="0.0372030292529531 0.028874703966386847 -0.035409145057201385" rpy="0 0 0" />
  </joint>
  <link name="left_ankle_roll_link_sensor_46">
    <inertial>
      <origin xyz="0 0 0" rpy="0 0 0" />
      <mass value="0.001" />
      <inertia ixx="1e-7" ixy="0" ixz="0" iyy="1e-7" iyz="0" izz="1e-7" />
    </inertial>
    <visual>
      <origin xyz="0 0 0" rpy="0 0 0" />
      <geometry>
        <box size="0.01 0.01 0.004" />
      </geometry>
      <material name="blue">
        <color rgba="0 0 1 1" />
      </material>
    </visual>
    <collision>
      <origin xyz="0 0 0" rpy="0 0 0" />
      <geometry>
        <box size="0.01 0.01 0.004" />
      </geometry>
    </collision>
  </link>
  <joint name="left_ankle_roll_link_sensor_46_joint" type="fixed">
    <parent link="left_ankle_roll_link" />
    <child link="left_ankle_roll_link_sensor_46" />
    <origin xyz="0.07091681886267169 0.026382393274782357 -0.035409145057201385" rpy="0 0 0" />
  </joint>
  <link name="left_ankle_roll_link_sensor_47">
    <inertial>
      <origin xyz="0 0 0" rpy="0 0 0" />
      <mass value="0.001" />
      <inertia ixx="1e-7" ixy="0" ixz="0" iyy="1e-7" iyz="0" izz="1e-7" />
    </inertial>
    <visual>
      <origin xyz="0 0 0" rpy="0 0 0" />
      <geometry>
        <box size="0.01 0.01 0.004" />
      </geometry>
      <material name="blue">
        <color rgba="0 0 1 1" />
      </material>
    </visual>
    <collision>
      <origin xyz="0 0 0" rpy="0 0 0" />
      <geometry>
        <box size="0.01 0.01 0.004" />
      </geometry>
    </collision>
  </link>
  <joint name="left_ankle_roll_link_sensor_47_joint" type="fixed">
    <parent link="left_ankle_roll_link" />
    <child link="left_ankle_roll_link_sensor_47" />
    <origin xyz="0.10496144732623251 0.025855155310038964 -0.035409145057201385" rpy="0 0 0" />
  </joint>
  <link name="left_ankle_roll_link_sensor_48">
    <inertial>
      <origin xyz="0 0 0" rpy="0 0 0" />
      <mass value="0.001" />
      <inertia ixx="1e-7" ixy="0" ixz="0" iyy="1e-7" iyz="0" izz="1e-7" />
    </inertial>
    <visual>
      <origin xyz="0 0 0" rpy="0 0 0" />
      <geometry>
        <box size="0.01 0.01 0.004" />
      </geometry>
      <material name="blue">
        <color rgba="0 0 1 1" />
      </material>
    </visual>
    <collision>
      <origin xyz="0 0 0" rpy="0 0 0" />
      <geometry>
        <box size="0.01 0.01 0.004" />
      </geometry>
    </collision>
  </link>
  <joint name="left_ankle_roll_link_sensor_48_joint" type="fixed">
    <parent link="left_ankle_roll_link" />
    <child link="left_ankle_roll_link_sensor_48" />
    <origin xyz="0.1312895268201828 0.023115674033761024 -0.035409145057201385" rpy="0 0 0" />
  </joint>
  <link name="right_ankle_roll_link_sensor_0">
    <inertial>
      <origin xyz="0 0 0" rpy="0 0 0" />
      <mass value="0.001" />
      <inertia ixx="1e-7" ixy="0" ixz="0" iyy="1e-7" iyz="0" izz="1e-7" />
    </inertial>
    <visual>
      <origin xyz="0 0 0" rpy="0 0 0" />
      <geometry>
        <box size="0.01 0.01 0.004" />
      </geometry>
      <material name="blue">
        <color rgba="0 0 1 1" />
      </material>
    </visual>
    <collision>
      <origin xyz="0 0 0" rpy="0 0 0" />
      <geometry>
        <box size="0.01 0.01 0.004" />
      </geometry>
    </collision>
  </link>
  <joint name="right_ankle_roll_link_sensor_0_joint" type="fixed">
    <parent link="right_ankle_roll_link" />
    <child link="right_ankle_roll_link_sensor_0" />
    <origin xyz="-0.05152185988034221 -0.020928998573039936 -0.035409145057201385" rpy="0 0 0" />
  </joint>
  <link name="right_ankle_roll_link_sensor_1">
    <inertial>
      <origin xyz="0 0 0" rpy="0 0 0" />
      <mass value="0.001" />
      <inertia ixx="1e-7" ixy="0" ixz="0" iyy="1e-7" iyz="0" izz="1e-7" />
    </inertial>
    <visual>
      <origin xyz="0 0 0" rpy="0 0 0" />
      <geometry>
        <box size="0.01 0.01 0.004" />
      </geometry>
      <material name="blue">
        <color rgba="0 0 1 1" />
      </material>
    </visual>
    <collision>
      <origin xyz="0 0 0" rpy="0 0 0" />
      <geometry>
        <box size="0.01 0.01 0.004" />
      </geometry>
    </collision>
  </link>
  <joint name="right_ankle_roll_link_sensor_1_joint" type="fixed">
    <parent link="right_ankle_roll_link" />
    <child link="right_ankle_roll_link_sensor_1" />
    <origin xyz="-0.03041028205981262 -0.02738614059429512 -0.035409145057201385" rpy="0 0 0" />
  </joint>
  <link name="right_ankle_roll_link_sensor_2">
    <inertial>
      <origin xyz="0 0 0" rpy="0 0 0" />
      <mass value="0.001" />
      <inertia ixx="1e-7" ixy="0" ixz="0" iyy="1e-7" iyz="0" izz="1e-7" />
    </inertial>
    <visual>
      <origin xyz="0 0 0" rpy="0 0 0" />
      <geometry>
        <box size="0.01 0.01 0.004" />
      </geometry>
      <material name="blue">
        <color rgba="0 0 1 1" />
      </material>
    </visual>
    <collision>
      <origin xyz="0 0 0" rpy="0 0 0" />
      <geometry>
        <box size="0.01 0.01 0.004" />
      </geometry>
    </collision>
  </link>
  <joint name="right_ankle_roll_link_sensor_2_joint" type="fixed">
    <parent link="right_ankle_roll_link" />
    <child link="right_ankle_roll_link_sensor_2" />
    <origin xyz="0.004059180358040036 -0.028005031016869932 -0.035409145057201385" rpy="0 0 0" />
  </joint>
  <link name="right_ankle_roll_link_sensor_3">
    <inertial>
      <origin xyz="0 0 0" rpy="0 0 0" />
      <mass value="0.001" />
      <inertia ixx="1e-7" ixy="0" ixz="0" iyy="1e-7" iyz="0" izz="1e-7" />
    </inertial>
    <visual>
      <origin xyz="0 0 0" rpy="0 0 0" />
      <geometry>
        <box size="0.01 0.01 0.004" />
      </geometry>
      <material name="blue">
        <color rgba="0 0 1 1" />
      </material>
    </visual>
    <collision>
      <origin xyz="0 0 0" rpy="0 0 0" />
      <geometry>
        <box size="0.01 0.01 0.004" />
      </geometry>
    </collision>
  </link>
  <joint name="right_ankle_roll_link_sensor_3_joint" type="fixed">
    <parent link="right_ankle_roll_link" />
    <child link="right_ankle_roll_link_sensor_3" />
    <origin xyz="0.03744334661330561 -0.02886953889508301 -0.035409145057201385" rpy="0 0 0" />
  </joint>
  <link name="right_ankle_roll_link_sensor_4">
    <inertial>
      <origin xyz="0 0 0" rpy="0 0 0" />
      <mass value="0.001" />
      <inertia ixx="1e-7" ixy="0" ixz="0" iyy="1e-7" iyz="0" izz="1e-7" />
    </inertial>
    <visual>
      <origin xyz="0 0 0" rpy="0 0 0" />
      <geometry>
        <box size="0.01 0.01 0.004" />
      </geometry>
      <material name="blue">
        <color rgba="0 0 1 1" />
      </material>
    </visual>
    <collision>
      <origin xyz="0 0 0" rpy="0 0 0" />
      <geometry>
        <box size="0.01 0.01 0.004" />
      </geometry>
    </collision>
  </link>
  <joint name="right_ankle_roll_link_sensor_4_joint" type="fixed">
    <parent link="right_ankle_roll_link" />
    <child link="right_ankle_roll_link_sensor_4" />
    <origin xyz="0.07091681886267169 -0.026382393274782357 -0.035409145057201385" rpy="0 0 0" />
  </joint>
  <link name="right_ankle_roll_link_sensor_5">
    <inertial>
      <origin xyz="0 0 0" rpy="0 0 0" />
      <mass value="0.001" />
      <inertia ixx="1e-7" ixy="0" ixz="0" iyy="1e-7" iyz="0" izz="1e-7" />
    </inertial>
    <visual>
      <origin xyz="0 0 0" rpy="0 0 0" />
      <geometry>
        <box size="0.01 0.01 0.004" />
      </geometry>
      <material name="blue">
        <color rgba="0 0 1 1" />
      </material>
    </visual>
    <collision>
      <origin xyz="0 0 0" rpy="0 0 0" />
      <geometry>
        <box size="0.01 0.01 0.004" />
      </geometry>
    </collision>
  </link>
  <joint name="right_ankle_roll_link_sensor_5_joint" type="fixed">
    <parent link="right_ankle_roll_link" />
    <child link="right_ankle_roll_link_sensor_5" />
    <origin xyz="0.10471389989576807 -0.025953373021419368 -0.035409145057201385" rpy="0 0 0" />
  </joint>
  <link name="right_ankle_roll_link_sensor_6">
    <inertial>
      <origin xyz="0 0 0" rpy="0 0 0" />
      <mass value="0.001" />
      <inertia ixx="1e-7" ixy="0" ixz="0" iyy="1e-7" iyz="0" izz="1e-7" />
    </inertial>
    <visual>
      <origin xyz="0 0 0" rpy="0 0 0" />
      <geometry>
        <box size="0.01 0.01 0.004" />
      </geometry>
      <material name="blue">
        <color rgba="0 0 1 1" />
      </material>
    </visual>
    <collision>
      <origin xyz="0 0 0" rpy="0 0 0" />
      <geometry>
        <box size="0.01 0.01 0.004" />
      </geometry>
    </collision>
  </link>
  <joint name="right_ankle_roll_link_sensor_6_joint" type="fixed">
    <parent link="right_ankle_roll_link" />
    <child link="right_ankle_roll_link_sensor_6" />
    <origin xyz="0.13094720244407654 -0.023374522104859352 -0.035409145057201385" rpy="0 0 0" />
  </joint>
  <link name="right_ankle_roll_link_sensor_7">
    <inertial>
      <origin xyz="0 0 0" rpy="0 0 0" />
      <mass value="0.001" />
      <inertia ixx="1e-7" ixy="0" ixz="0" iyy="1e-7" iyz="0" izz="1e-7" />
    </inertial>
    <visual>
      <origin xyz="0 0 0" rpy="0 0 0" />
      <geometry>
        <box size="0.01 0.01 0.004" />
      </geometry>
      <material name="blue">
        <color rgba="0 0 1 1" />
      </material>
    </visual>
    <collision>
      <origin xyz="0 0 0" rpy="0 0 0" />
      <geometry>
        <box size="0.01 0.01 0.004" />
      </geometry>
    </collision>
  </link>
  <joint name="right_ankle_roll_link_sensor_7_joint" type="fixed">
    <parent link="right_ankle_roll_link" />
    <child link="right_ankle_roll_link_sensor_7" />
    <origin xyz="-0.05468999799628186 -0.01672481232289301 -0.035409145057201385" rpy="0 0 0" />
  </joint>
  <link name="right_ankle_roll_link_sensor_8">
    <inertial>
      <origin xyz="0 0 0" rpy="0 0 0" />
      <mass value="0.001" />
      <inertia ixx="1e-7" ixy="0" ixz="0" iyy="1e-7" iyz="0" izz="1e-7" />
    </inertial>
    <visual>
      <origin xyz="0 0 0" rpy="0 0 0" />
      <geometry>
        <box size="0.01 0.01 0.004" />
      </geometry>
      <material name="blue">
        <color rgba="0 0 1 1" />
      </material>
    </visual>
    <collision>
      <origin xyz="0 0 0" rpy="0 0 0" />
      <geometry>
        <box size="0.01 0.01 0.004" />
      </geometry>
    </collision>
  </link>
  <joint name="right_ankle_roll_link_sensor_8_joint" type="fixed">
    <parent link="right_ankle_roll_link" />
    <child link="right_ankle_roll_link_sensor_8" />
    <origin xyz="-0.0313277469941269 -0.026617733549849767 -0.035409145057201385" rpy="0 0 0" />
  </joint>
  <link name="right_ankle_roll_link_sensor_9">
    <inertial>
      <origin xyz="0 0 0" rpy="0 0 0" />
      <mass value="0.001" />
      <inertia ixx="1e-7" ixy="0" ixz="0" iyy="1e-7" iyz="0" izz="1e-7" />
    </inertial>
    <visual>
      <origin xyz="0 0 0" rpy="0 0 0" />
      <geometry>
        <box size="0.01 0.01 0.004" />
      </geometry>
      <material name="blue">
        <color rgba="0 0 1 1" />
      </material>
    </visual>
    <collision>
      <origin xyz="0 0 0" rpy="0 0 0" />
      <geometry>
        <box size="0.01 0.01 0.004" />
      </geometry>
    </collision>
  </link>
  <joint name="right_ankle_roll_link_sensor_9_joint" type="fixed">
    <parent link="right_ankle_roll_link" />
    <child link="right_ankle_roll_link_sensor_9" />
    <origin xyz="0.00357793349989041 -0.024846397227688177 -0.035409145057201385" rpy="0 0 0" />
  </joint>
  <link name="right_ankle_roll_link_sensor_10">
    <inertial>
      <origin xyz="0 0 0" rpy="0 0 0" />
      <mass value="0.001" />
      <inertia ixx="1e-7" ixy="0" ixz="0" iyy="1e-7" iyz="0" izz="1e-7" />
    </inertial>
    <visual>
      <origin xyz="0 0 0" rpy="0 0 0" />
      <geometry>
        <box size="0.01 0.01 0.004" />
      </geometry>
      <material name="blue">
        <color rgba="0 0 1 1" />
      </material>
    </visual>
    <collision>
      <origin xyz="0 0 0" rpy="0 0 0" />
      <geometry>
        <box size="0.01 0.01 0.004" />
      </geometry>
    </collision>
  </link>
  <joint name="right_ankle_roll_link_sensor_10_joint" type="fixed">
    <parent link="right_ankle_roll_link" />
    <child link="right_ankle_roll_link_sensor_10" />
    <origin xyz="0.03814782263652075 -0.024497435592205883 -0.035409145057201385" rpy="0 0 0" />
  </joint>
  <link name="right_ankle_roll_link_sensor_11">
    <inertial>
      <origin xyz="0 0 0" rpy="0 0 0" />
      <mass value="0.001" />
      <inertia ixx="1e-7" ixy="0" ixz="0" iyy="1e-7" iyz="0" izz="1e-7" />
    </inertial>
    <visual>
      <origin xyz="0 0 0" rpy="0 0 0" />
      <geometry>
        <box size="0.01 0.01 0.004" />
      </geometry>
      <material name="blue">
        <color rgba="0 0 1 1" />
      </material>
    </visual>
    <collision>
      <origin xyz="0 0 0" rpy="0 0 0" />
      <geometry>
        <box size="0.01 0.01 0.004" />
      </geometry>
    </collision>
  </link>
  <joint name="right_ankle_roll_link_sensor_11_joint" type="fixed">
    <parent link="right_ankle_roll_link" />
    <child link="right_ankle_roll_link_sensor_11" />
    <origin xyz="0.07187671672392552 -0.022980581989981968 -0.035409145057201385" rpy="0 0 0" />
  </joint>
  <link name="right_ankle_roll_link_sensor_12">
    <inertial>
      <origin xyz="0 0 0" rpy="0 0 0" />
      <mass value="0.001" />
      <inertia ixx="1e-7" ixy="0" ixz="0" iyy="1e-7" iyz="0" izz="1e-7" />
    </inertial>
    <visual>
      <origin xyz="0 0 0" rpy="0 0 0" />
      <geometry>
        <box size="0.01 0.01 0.004" />
      </geometry>
      <material name="blue">
        <color rgba="0 0 1 1" />
      </material>
    </visual>
    <collision>
      <origin xyz="0 0 0" rpy="0 0 0" />
      <geometry>
        <box size="0.01 0.01 0.004" />
      </geometry>
    </collision>
  </link>
  <joint name="right_ankle_roll_link_sensor_12_joint" type="fixed">
    <parent link="right_ankle_roll_link" />
    <child link="right_ankle_roll_link_sensor_12" />
    <origin xyz="0.1043953294899373 -0.020356481670025635 -0.035409145057201385" rpy="0 0 0" />
  </joint>
  <link name="right_ankle_roll_link_sensor_13">
    <inertial>
      <origin xyz="0 0 0" rpy="0 0 0" />
      <mass value="0.001" />
      <inertia ixx="1e-7" ixy="0" ixz="0" iyy="1e-7" iyz="0" izz="1e-7" />
    </inertial>
    <visual>
      <origin xyz="0 0 0" rpy="0 0 0" />
      <geometry>
        <box size="0.01 0.01 0.004" />
      </geometry>
      <material name="blue">
        <color rgba="0 0 1 1" />
      </material>
    </visual>
    <collision>
      <origin xyz="0 0 0" rpy="0 0 0" />
      <geometry>
        <box size="0.01 0.01 0.004" />
      </geometry>
    </collision>
  </link>
  <joint name="right_ankle_roll_link_sensor_13_joint" type="fixed">
    <parent link="right_ankle_roll_link" />
    <child link="right_ankle_roll_link_sensor_13" />
    <origin xyz="0.1333885536811086 -0.01707114036162157 -0.035409145057201385" rpy="0 0 0" />
  </joint>
  <link name="right_ankle_roll_link_sensor_14">
    <inertial>
      <origin xyz="0 0 0" rpy="0 0 0" />
      <mass value="0.001" />
      <inertia ixx="1e-7" ixy="0" ixz="0" iyy="1e-7" iyz="0" izz="1e-7" />
    </inertial>
    <visual>
      <origin xyz="0 0 0" rpy="0 0 0" />
      <geometry>
        <box size="0.01 0.01 0.004" />
      </geometry>
      <material name="blue">
        <color rgba="0 0 1 1" />
      </material>
    </visual>
    <collision>
      <origin xyz="0 0 0" rpy="0 0 0" />
      <geometry>
        <box size="0.01 0.01 0.004" />
      </geometry>
    </collision>
  </link>
  <joint name="right_ankle_roll_link_sensor_14_joint" type="fixed">
    <parent link="right_ankle_roll_link" />
    <child link="right_ankle_roll_link_sensor_14" />
    <origin xyz="-0.05794387204414322 -0.010486026496501518 -0.035409145057201385" rpy="0 0 0" />
  </joint>
  <link name="right_ankle_roll_link_sensor_15">
    <inertial>
      <origin xyz="0 0 0" rpy="0 0 0" />
      <mass value="0.001" />
      <inertia ixx="1e-7" ixy="0" ixz="0" iyy="1e-7" iyz="0" izz="1e-7" />
    </inertial>
    <visual>
      <origin xyz="0 0 0" rpy="0 0 0" />
      <geometry>
        <box size="0.01 0.01 0.004" />
      </geometry>
      <material name="blue">
        <color rgba="0 0 1 1" />
      </material>
    </visual>
    <collision>
      <origin xyz="0 0 0" rpy="0 0 0" />
      <geometry>
        <box size="0.01 0.01 0.004" />
      </geometry>
    </collision>
  </link>
  <joint name="right_ankle_roll_link_sensor_15_joint" type="fixed">
    <parent link="right_ankle_roll_link" />
    <child link="right_ankle_roll_link_sensor_15" />
    <origin xyz="-0.026499991257030585 -0.012646673083963802 -0.035409145057201385" rpy="0 0 0" />
  </joint>
  <link name="right_ankle_roll_link_sensor_16">
    <inertial>
      <origin xyz="0 0 0" rpy="0 0 0" />
      <mass value="0.001" />
      <inertia ixx="1e-7" ixy="0" ixz="0" iyy="1e-7" iyz="0" izz="1e-7" />
    </inertial>
    <visual>
      <origin xyz="0 0 0" rpy="0 0 0" />
      <geometry>
        <box size="0.01 0.01 0.004" />
      </geometry>
      <material name="blue">
        <color rgba="0 0 1 1" />
      </material>
    </visual>
    <collision>
      <origin xyz="0 0 0" rpy="0 0 0" />
      <geometry>
        <box size="0.01 0.01 0.004" />
      </geometry>
    </collision>
  </link>
  <joint name="right_ankle_roll_link_sensor_16_joint" type="fixed">
    <parent link="right_ankle_roll_link" />
    <child link="right_ankle_roll_link_sensor_16" />
    <origin xyz="0.0030461061646167033 -0.024635589597541026 -0.035409145057201385" rpy="0 0 0" />
  </joint>
  <link name="right_ankle_roll_link_sensor_17">
    <inertial>
      <origin xyz="0 0 0" rpy="0 0 0" />
      <mass value="0.001" />
      <inertia ixx="1e-7" ixy="0" ixz="0" iyy="1e-7" iyz="0" izz="1e-7" />
    </inertial>
    <visual>
      <origin xyz="0 0 0" rpy="0 0 0" />
      <geometry>
        <box size="0.01 0.01 0.004" />
      </geometry>
      <material name="blue">
        <color rgba="0 0 1 1" />
      </material>
    </visual>
    <collision>
      <origin xyz="0 0 0" rpy="0 0 0" />
      <geometry>
        <box size="0.01 0.01 0.004" />
      </geometry>
    </collision>
  </link>
  <joint name="right_ankle_roll_link_sensor_17_joint" type="fixed">
    <parent link="right_ankle_roll_link" />
    <child link="right_ankle_roll_link_sensor_17" />
    <origin xyz="0.0396506008242065 -0.02266048856743494 -0.035409145057201385" rpy="0 0 0" />
  </joint>
  <link name="right_ankle_roll_link_sensor_18">
    <inertial>
      <origin xyz="0 0 0" rpy="0 0 0" />
      <mass value="0.001" />
      <inertia ixx="1e-7" ixy="0" ixz="0" iyy="1e-7" iyz="0" izz="1e-7" />
    </inertial>
    <visual>
      <origin xyz="0 0 0" rpy="0 0 0" />
      <geometry>
        <box size="0.01 0.01 0.004" />
      </geometry>
      <material name="blue">
        <color rgba="0 0 1 1" />
      </material>
    </visual>
    <collision>
      <origin xyz="0 0 0" rpy="0 0 0" />
      <geometry>
        <box size="0.01 0.01 0.004" />
      </geometry>
    </collision>
  </link>
  <joint name="right_ankle_roll_link_sensor_18_joint" type="fixed">
    <parent link="right_ankle_roll_link" />
    <child link="right_ankle_roll_link_sensor_18" />
    <origin xyz="0.0727271252849399 -0.0124747704520709 -0.035409145057201385" rpy="0 0 0" />
  </joint>
  <link name="right_ankle_roll_link_sensor_19">
    <inertial>
      <origin xyz="0 0 0" rpy="0 0 0" />
      <mass value="0.001" />
      <inertia ixx="1e-7" ixy="0" ixz="0" iyy="1e-7" iyz="0" izz="1e-7" />
    </inertial>
    <visual>
      <origin xyz="0 0 0" rpy="0 0 0" />
      <geometry>
        <box size="0.01 0.01 0.004" />
      </geometry>
      <material name="blue">
        <color rgba="0 0 1 1" />
      </material>
    </visual>
    <collision>
      <origin xyz="0 0 0" rpy="0 0 0" />
      <geometry>
        <box size="0.01 0.01 0.004" />
      </geometry>
    </collision>
  </link>
  <joint name="right_ankle_roll_link_sensor_19_joint" type="fixed">
    <parent link="right_ankle_roll_link" />
    <child link="right_ankle_roll_link_sensor_19" />
    <origin xyz="0.10457482796474882 -0.011233994821511363 -0.035409145057201385" rpy="0 0 0" />
  </joint>
  <link name="right_ankle_roll_link_sensor_20">
    <inertial>
      <origin xyz="0 0 0" rpy="0 0 0" />
      <mass value="0.001" />
      <inertia ixx="1e-7" ixy="0" ixz="0" iyy="1e-7" iyz="0" izz="1e-7" />
    </inertial>
    <visual>
      <origin xyz="0 0 0" rpy="0 0 0" />
      <geometry>
        <box size="0.01 0.01 0.004" />
      </geometry>
      <material name="blue">
        <color rgba="0 0 1 1" />
      </material>
    </visual>
    <collision>
      <origin xyz="0 0 0" rpy="0 0 0" />
      <geometry>
        <box size="0.01 0.01 0.004" />
      </geometry>
    </collision>
  </link>
  <joint name="right_ankle_roll_link_sensor_20_joint" type="fixed">
    <parent link="right_ankle_roll_link" />
    <child link="right_ankle_roll_link_sensor_20" />
    <origin xyz="0.13684036963432133 -0.010383461167274588 -0.035409145057201385" rpy="0 0 0" />
  </joint>
  <link name="right_ankle_roll_link_sensor_21">
    <inertial>
      <origin xyz="0 0 0" rpy="0 0 0" />
      <mass value="0.001" />
      <inertia ixx="1e-7" ixy="0" ixz="0" iyy="1e-7" iyz="0" izz="1e-7" />
    </inertial>
    <visual>
      <origin xyz="0 0 0" rpy="0 0 0" />
      <geometry>
        <box size="0.01 0.01 0.004" />
      </geometry>
      <material name="blue">
        <color rgba="0 0 1 1" />
      </material>
    </visual>
    <collision>
      <origin xyz="0 0 0" rpy="0 0 0" />
      <geometry>
        <box size="0.01 0.01 0.004" />
      </geometry>
    </collision>
  </link>
  <joint name="right_ankle_roll_link_sensor_21_joint" type="fixed">
    <parent link="right_ankle_roll_link" />
    <child link="right_ankle_roll_link_sensor_21" />
    <origin xyz="-0.05922419821173717 -0.00010739565682747304 -0.035409145057201385" rpy="0 0 0" />
  </joint>
  <link name="right_ankle_roll_link_sensor_22">
    <inertial>
      <origin xyz="0 0 0" rpy="0 0 0" />
      <mass value="0.001" />
      <inertia ixx="1e-7" ixy="0" ixz="0" iyy="1e-7" iyz="0" izz="1e-7" />
    </inertial>
    <visual>
      <origin xyz="0 0 0" rpy="0 0 0" />
      <geometry>
        <box size="0.01 0.01 0.004" />
      </geometry>
      <material name="blue">
        <color rgba="0 0 1 1" />
      </material>
    </visual>
    <collision>
      <origin xyz="0 0 0" rpy="0 0 0" />
      <geometry>
        <box size="0.01 0.01 0.004" />
      </geometry>
    </collision>
  </link>
  <joint name="right_ankle_roll_link_sensor_22_joint" type="fixed">
    <parent link="right_ankle_roll_link" />
    <child link="right_ankle_roll_link_sensor_22" />
    <origin xyz="-0.0262499908001741 0.005984953963802079 -0.035409145057201385" rpy="0 0 0" />
  </joint>
  <link name="right_ankle_roll_link_sensor_23">
    <inertial>
      <origin xyz="0 0 0" rpy="0 0 0" />
      <mass value="0.001" />
      <inertia ixx="1e-7" ixy="0" ixz="0" iyy="1e-7" iyz="0" izz="1e-7" />
    </inertial>
    <visual>
      <origin xyz="0 0 0" rpy="0 0 0" />
      <geometry>
        <box size="0.01 0.01 0.004" />
      </geometry>
      <material name="blue">
        <color rgba="0 0 1 1" />
      </material>
    </visual>
    <collision>
      <origin xyz="0 0 0" rpy="0 0 0" />
      <geometry>
        <box size="0.01 0.01 0.004" />
      </geometry>
    </collision>
  </link>
  <joint name="right_ankle_roll_link_sensor_23_joint" type="fixed">
    <parent link="right_ankle_roll_link" />
    <child link="right_ankle_roll_link_sensor_23" />
    <origin xyz="0.003560895586819504 -4.9561292295427495e-05 -0.035409145057201385" rpy="0 0 0" />
  </joint>
  <link name="right_ankle_roll_link_sensor_24">
    <inertial>
      <origin xyz="0 0 0" rpy="0 0 0" />
      <mass value="0.001" />
      <inertia ixx="1e-7" ixy="0" ixz="0" iyy="1e-7" iyz="0" izz="1e-7" />
    </inertial>
    <visual>
      <origin xyz="0 0 0" rpy="0 0 0" />
      <geometry>
        <box size="0.01 0.01 0.004" />
      </geometry>
      <material name="blue">
        <color rgba="0 0 1 1" />
      </material>
    </visual>
    <collision>
      <origin xyz="0 0 0" rpy="0 0 0" />
      <geometry>
        <box size="0.01 0.01 0.004" />
      </geometry>
    </collision>
  </link>
  <joint name="right_ankle_roll_link_sensor_24_joint" type="fixed">
    <parent link="right_ankle_roll_link" />
    <child link="right_ankle_roll_link_sensor_24" />
    <origin xyz="0.03826199186460405 -4.9557884535766233e-05 -0.035409145057201385" rpy="0 0 0" />
  </joint>
  <link name="right_ankle_roll_link_sensor_25">
    <inertial>
      <origin xyz="0 0 0" rpy="0 0 0" />
      <mass value="0.001" />
      <inertia ixx="1e-7" ixy="0" ixz="0" iyy="1e-7" iyz="0" izz="1e-7" />
    </inertial>
    <visual>
      <origin xyz="0 0 0" rpy="0 0 0" />
      <geometry>
        <box size="0.01 0.01 0.004" />
      </geometry>
      <material name="blue">
        <color rgba="0 0 1 1" />
      </material>
    </visual>
    <collision>
      <origin xyz="0 0 0" rpy="0 0 0" />
      <geometry>
        <box size="0.01 0.01 0.004" />
      </geometry>
    </collision>
  </link>
  <joint name="right_ankle_roll_link_sensor_25_joint" type="fixed">
    <parent link="right_ankle_roll_link" />
    <child link="right_ankle_roll_link_sensor_25" />
    <origin xyz="0.07317574212146999 -4.80390740748432e-05 -0.035409145057201385" rpy="0 0 0" />
  </joint>
  <link name="right_ankle_roll_link_sensor_26">
    <inertial>
      <origin xyz="0 0 0" rpy="0 0 0" />
      <mass value="0.001" />
      <inertia ixx="1e-7" ixy="0" ixz="0" iyy="1e-7" iyz="0" izz="1e-7" />
    </inertial>
    <visual>
      <origin xyz="0 0 0" rpy="0 0 0" />
      <geometry>
        <box size="0.01 0.01 0.004" />
      </geometry>
      <material name="blue">
        <color rgba="0 0 1 1" />
      </material>
    </visual>
    <collision>
      <origin xyz="0 0 0" rpy="0 0 0" />
      <geometry>
        <box size="0.01 0.01 0.004" />
      </geometry>
    </collision>
  </link>
  <joint name="right_ankle_roll_link_sensor_26_joint" type="fixed">
    <parent link="right_ankle_roll_link" />
    <child link="right_ankle_roll_link_sensor_26" />
    <origin xyz="0.10490959703756027 2.362343020577114e-06 -0.035409145057201385" rpy="0 0 0" />
  </joint>
  <link name="right_ankle_roll_link_sensor_27">
    <inertial>
      <origin xyz="0 0 0" rpy="0 0 0" />
      <mass value="0.001" />
      <inertia ixx="1e-7" ixy="0" ixz="0" iyy="1e-7" iyz="0" izz="1e-7" />
    </inertial>
    <visual>
      <origin xyz="0 0 0" rpy="0 0 0" />
      <geometry>
        <box size="0.01 0.01 0.004" />
      </geometry>
      <material name="blue">
        <color rgba="0 0 1 1" />
      </material>
    </visual>
    <collision>
      <origin xyz="0 0 0" rpy="0 0 0" />
      <geometry>
        <box size="0.01 0.01 0.004" />
      </geometry>
    </collision>
  </link>
  <joint name="right_ankle_roll_link_sensor_27_joint" type="fixed">
    <parent link="right_ankle_roll_link" />
    <child link="right_ankle_roll_link_sensor_27" />
    <origin xyz="0.13776152423912533 -6.440720240348226e-05 -0.035409145057201385" rpy="0 0 0" />
  </joint>
  <link name="right_ankle_roll_link_sensor_28">
    <inertial>
      <origin xyz="0 0 0" rpy="0 0 0" />
      <mass value="0.001" />
      <inertia ixx="1e-7" ixy="0" ixz="0" iyy="1e-7" iyz="0" izz="1e-7" />
    </inertial>
    <visual>
      <origin xyz="0 0 0" rpy="0 0 0" />
      <geometry>
        <box size="0.01 0.01 0.004" />
      </geometry>
      <material name="blue">
        <color rgba="0 0 1 1" />
      </material>
    </visual>
    <collision>
      <origin xyz="0 0 0" rpy="0 0 0" />
      <geometry>
        <box size="0.01 0.01 0.004" />
      </geometry>
    </collision>
  </link>
  <joint name="right_ankle_roll_link_sensor_28_joint" type="fixed">
    <parent link="right_ankle_roll_link" />
    <child link="right_ankle_roll_link_sensor_28" />
    <origin xyz="-0.05796601996607482 0.010333814786470795 -0.035409145057201385" rpy="0 0 0" />
  </joint>
  <link name="right_ankle_roll_link_sensor_29">
    <inertial>
      <origin xyz="0 0 0" rpy="0 0 0" />
      <mass value="0.001" />
      <inertia ixx="1e-7" ixy="0" ixz="0" iyy="1e-7" iyz="0" izz="1e-7" />
    </inertial>
    <visual>
      <origin xyz="0 0 0" rpy="0 0 0" />
      <geometry>
        <box size="0.01 0.01 0.004" />
      </geometry>
      <material name="blue">
        <color rgba="0 0 1 1" />
      </material>
    </visual>
    <collision>
      <origin xyz="0 0 0" rpy="0 0 0" />
      <geometry>
        <box size="0.01 0.01 0.004" />
      </geometry>
    </collision>
  </link>
  <joint name="right_ankle_roll_link_sensor_29_joint" type="fixed">
    <parent link="right_ankle_roll_link" />
    <child link="right_ankle_roll_link_sensor_29" />
    <origin xyz="-0.026499983852078746 0.01254755427615068 -0.035409145057201385" rpy="0 0 0" />
  </joint>
  <link name="right_ankle_roll_link_sensor_30">
    <inertial>
      <origin xyz="0 0 0" rpy="0 0 0" />
      <mass value="0.001" />
      <inertia ixx="1e-7" ixy="0" ixz="0" iyy="1e-7" iyz="0" izz="1e-7" />
    </inertial>
    <visual>
      <origin xyz="0 0 0" rpy="0 0 0" />
      <geometry>
        <box size="0.01 0.01 0.004" />
      </geometry>
      <material name="blue">
        <color rgba="0 0 1 1" />
      </material>
    </visual>
    <collision>
      <origin xyz="0 0 0" rpy="0 0 0" />
      <geometry>
        <box size="0.01 0.01 0.004" />
      </geometry>
    </collision>
  </link>
  <joint name="right_ankle_roll_link_sensor_30_joint" type="fixed">
    <parent link="right_ankle_roll_link" />
    <child link="right_ankle_roll_link_sensor_30" />
    <origin xyz="0.003049883399648701 0.024440679728048503 -0.035409145057201385" rpy="0 0 0" />
  </joint>
  <link name="right_ankle_roll_link_sensor_31">
    <inertial>
      <origin xyz="0 0 0" rpy="0 0 0" />
      <mass value="0.001" />
      <inertia ixx="1e-7" ixy="0" ixz="0" iyy="1e-7" iyz="0" izz="1e-7" />
    </inertial>
    <visual>
      <origin xyz="0 0 0" rpy="0 0 0" />
      <geometry>
        <box size="0.01 0.01 0.004" />
      </geometry>
      <material name="blue">
        <color rgba="0 0 1 1" />
      </material>
    </visual>
    <collision>
      <origin xyz="0 0 0" rpy="0 0 0" />
      <geometry>
        <box size="0.01 0.01 0.004" />
      </geometry>
    </collision>
  </link>
  <joint name="right_ankle_roll_link_sensor_31_joint" type="fixed">
    <parent link="right_ankle_roll_link" />
    <child link="right_ankle_roll_link_sensor_31" />
    <origin xyz="0.03963900922375675 0.022478250054329258 -0.035409145057201385" rpy="0 0 0" />
  </joint>
  <link name="right_ankle_roll_link_sensor_32">
    <inertial>
      <origin xyz="0 0 0" rpy="0 0 0" />
      <mass value="0.001" />
      <inertia ixx="1e-7" ixy="0" ixz="0" iyy="1e-7" iyz="0" izz="1e-7" />
    </inertial>
    <visual>
      <origin xyz="0 0 0" rpy="0 0 0" />
      <geometry>
        <box size="0.01 0.01 0.004" />
      </geometry>
      <material name="blue">
        <color rgba="0 0 1 1" />
      </material>
    </visual>
    <collision>
      <origin xyz="0 0 0" rpy="0 0 0" />
      <geometry>
        <box size="0.01 0.01 0.004" />
      </geometry>
    </collision>
  </link>
  <joint name="right_ankle_roll_link_sensor_32_joint" type="fixed">
    <parent link="right_ankle_roll_link" />
    <child link="right_ankle_roll_link_sensor_32" />
    <origin xyz="0.07271739213951815 0.012406782227277648 -0.035409145057201385" rpy="0 0 0" />
  </joint>
  <link name="right_ankle_roll_link_sensor_33">
    <inertial>
      <origin xyz="0 0 0" rpy="0 0 0" />
      <mass value="0.001" />
      <inertia ixx="1e-7" ixy="0" ixz="0" iyy="1e-7" iyz="0" izz="1e-7" />
    </inertial>
    <visual>
      <origin xyz="0 0 0" rpy="0 0 0" />
      <geometry>
        <box size="0.01 0.01 0.004" />
      </geometry>
      <material name="blue">
        <color rgba="0 0 1 1" />
      </material>
    </visual>
    <collision>
      <origin xyz="0 0 0" rpy="0 0 0" />
      <geometry>
        <box size="0.01 0.01 0.004" />
      </geometry>
    </collision>
  </link>
  <joint name="right_ankle_roll_link_sensor_33_joint" type="fixed">
    <parent link="right_ankle_roll_link" />
    <child link="right_ankle_roll_link_sensor_33" />
    <origin xyz="0.10457053378734785 0.011151025291145214 -0.035409145057201385" rpy="0 0 0" />
  </joint>
  <link name="right_ankle_roll_link_sensor_34">
    <inertial>
      <origin xyz="0 0 0" rpy="0 0 0" />
      <mass value="0.001" />
      <inertia ixx="1e-7" ixy="0" ixz="0" iyy="1e-7" iyz="0" izz="1e-7" />
    </inertial>
    <visual>
      <origin xyz="0 0 0" rpy="0 0 0" />
      <geometry>
        <box size="0.01 0.01 0.004" />
      </geometry>
      <material name="blue">
        <color rgba="0 0 1 1" />
      </material>
    </visual>
    <collision>
      <origin xyz="0 0 0" rpy="0 0 0" />
      <geometry>
        <box size="0.01 0.01 0.004" />
      </geometry>
    </collision>
  </link>
  <joint name="right_ankle_roll_link_sensor_34_joint" type="fixed">
    <parent link="right_ankle_roll_link" />
    <child link="right_ankle_roll_link_sensor_34" />
    <origin xyz="0.13666261524746184 0.01050881576071932 -0.035409145057201385" rpy="0 0 0" />
  </joint>
  <link name="right_ankle_roll_link_sensor_35">
    <inertial>
      <origin xyz="0 0 0" rpy="0 0 0" />
      <mass value="0.001" />
      <inertia ixx="1e-7" ixy="0" ixz="0" iyy="1e-7" iyz="0" izz="1e-7" />
    </inertial>
    <visual>
      <origin xyz="0 0 0" rpy="0 0 0" />
      <geometry>
        <box size="0.01 0.01 0.004" />
      </geometry>
      <material name="blue">
        <color rgba="0 0 1 1" />
      </material>
    </visual>
    <collision>
      <origin xyz="0 0 0" rpy="0 0 0" />
      <geometry>
        <box size="0.01 0.01 0.004" />
      </geometry>
    </collision>
  </link>
  <joint name="right_ankle_roll_link_sensor_35_joint" type="fixed">
    <parent link="right_ankle_roll_link" />
    <child link="right_ankle_roll_link_sensor_35" />
    <origin xyz="-0.05431328938811975 0.017053972029563106 -0.035409145057201385" rpy="0 0 0" />
  </joint>
  <link name="right_ankle_roll_link_sensor_36">
    <inertial>
      <origin xyz="0 0 0" rpy="0 0 0" />
      <mass value="0.001" />
      <inertia ixx="1e-7" ixy="0" ixz="0" iyy="1e-7" iyz="0" izz="1e-7" />
    </inertial>
    <visual>
      <origin xyz="0 0 0" rpy="0 0 0" />
      <geometry>
        <box size="0.01 0.01 0.004" />
      </geometry>
      <material name="blue">
        <color rgba="0 0 1 1" />
      </material>
    </visual>
    <collision>
      <origin xyz="0 0 0" rpy="0 0 0" />
      <geometry>
        <box size="0.01 0.01 0.004" />
      </geometry>
    </collision>
  </link>
  <joint name="right_ankle_roll_link_sensor_36_joint" type="fixed">
    <parent link="right_ankle_roll_link" />
    <child link="right_ankle_roll_link_sensor_36" />
    <origin xyz="-0.03134880546545046 0.02640434144820047 -0.035409145057201385" rpy="0 0 0" />
  </joint>
  <link name="right_ankle_roll_link_sensor_37">
    <inertial>
      <origin xyz="0 0 0" rpy="0 0 0" />
      <mass value="0.001" />
      <inertia ixx="1e-7" ixy="0" ixz="0" iyy="1e-7" iyz="0" izz="1e-7" />
    </inertial>
    <visual>
      <origin xyz="0 0 0" rpy="0 0 0" />
      <geometry>
        <box size="0.01 0.01 0.004" />
      </geometry>
      <material name="blue">
        <color rgba="0 0 1 1" />
      </material>
    </visual>
    <collision>
      <origin xyz="0 0 0" rpy="0 0 0" />
      <geometry>
        <box size="0.01 0.01 0.004" />
      </geometry>
    </collision>
  </link>
  <joint name="right_ankle_roll_link_sensor_37_joint" type="fixed">
    <parent link="right_ankle_roll_link" />
    <child link="right_ankle_roll_link_sensor_37" />
    <origin xyz="0.003582059224127682 0.02465152190223807 -0.035409145057201385" rpy="0 0 0" />
  </joint>
  <link name="right_ankle_roll_link_sensor_38">
    <inertial>
      <origin xyz="0 0 0" rpy="0 0 0" />
      <mass value="0.001" />
      <inertia ixx="1e-7" ixy="0" ixz="0" iyy="1e-7" iyz="0" izz="1e-7" />
    </inertial>
    <visual>
      <origin xyz="0 0 0" rpy="0 0 0" />
      <geometry>
        <box size="0.01 0.01 0.004" />
      </geometry>
      <material name="blue">
        <color rgba="0 0 1 1" />
      </material>
    </visual>
    <collision>
      <origin xyz="0 0 0" rpy="0 0 0" />
      <geometry>
        <box size="0.01 0.01 0.004" />
      </geometry>
    </collision>
  </link>
  <joint name="right_ankle_roll_link_sensor_38_joint" type="fixed">
    <parent link="right_ankle_roll_link" />
    <child link="right_ankle_roll_link_sensor_38" />
    <origin xyz="0.038135652541645526 0.024318699218689933 -0.035409145057201385" rpy="0 0 0" />
  </joint>
  <link name="right_ankle_roll_link_sensor_39">
    <inertial>
      <origin xyz="0 0 0" rpy="0 0 0" />
      <mass value="0.001" />
      <inertia ixx="1e-7" ixy="0" ixz="0" iyy="1e-7" iyz="0" izz="1e-7" />
    </inertial>
    <visual>
      <origin xyz="0 0 0" rpy="0 0 0" />
      <geometry>
        <box size="0.01 0.01 0.004" />
      </geometry>
      <material name="blue">
        <color rgba="0 0 1 1" />
      </material>
    </visual>
    <collision>
      <origin xyz="0 0 0" rpy="0 0 0" />
      <geometry>
        <box size="0.01 0.01 0.004" />
      </geometry>
    </collision>
  </link>
  <joint name="right_ankle_roll_link_sensor_39_joint" type="fixed">
    <parent link="right_ankle_roll_link" />
    <child link="right_ankle_roll_link_sensor_39" />
    <origin xyz="0.07179707432187356 0.02294339523416318 -0.035409145057201385" rpy="0 0 0" />
  </joint>
  <link name="right_ankle_roll_link_sensor_40">
    <inertial>
      <origin xyz="0 0 0" rpy="0 0 0" />
      <mass value="0.001" />
      <inertia ixx="1e-7" ixy="0" ixz="0" iyy="1e-7" iyz="0" izz="1e-7" />
    </inertial>
    <visual>
      <origin xyz="0 0 0" rpy="0 0 0" />
      <geometry>
        <box size="0.01 0.01 0.004" />
      </geometry>
      <material name="blue">
        <color rgba="0 0 1 1" />
      </material>
    </visual>
    <collision>
      <origin xyz="0 0 0" rpy="0 0 0" />
      <geometry>
        <box size="0.01 0.01 0.004" />
      </geometry>
    </collision>
  </link>
  <joint name="right_ankle_roll_link_sensor_40_joint" type="fixed">
    <parent link="right_ankle_roll_link" />
    <child link="right_ankle_roll_link_sensor_40" />
    <origin xyz="0.10432623214342915 0.02050059748946359 -0.035409145057201385" rpy="0 0 0" />
  </joint>
  <link name="right_ankle_roll_link_sensor_41">
    <inertial>
      <origin xyz="0 0 0" rpy="0 0 0" />
      <mass value="0.001" />
      <inertia ixx="1e-7" ixy="0" ixz="0" iyy="1e-7" iyz="0" izz="1e-7" />
    </inertial>
    <visual>
      <origin xyz="0 0 0" rpy="0 0 0" />
      <geometry>
        <box size="0.01 0.01 0.004" />
      </geometry>
      <material name="blue">
        <color rgba="0 0 1 1" />
      </material>
    </visual>
    <collision>
      <origin xyz="0 0 0" rpy="0 0 0" />
      <geometry>
        <box size="0.01 0.01 0.004" />
      </geometry>
    </collision>
  </link>
  <joint name="right_ankle_roll_link_sensor_41_joint" type="fixed">
    <parent link="right_ankle_roll_link" />
    <child link="right_ankle_roll_link_sensor_41" />
    <origin xyz="0.13327977061271667 0.0171144288033247 -0.035409145057201385" rpy="0 0 0" />
  </joint>
  <link name="right_ankle_roll_link_sensor_42">
    <inertial>
      <origin xyz="0 0 0" rpy="0 0 0" />
      <mass value="0.001" />
      <inertia ixx="1e-7" ixy="0" ixz="0" iyy="1e-7" iyz="0" izz="1e-7" />
    </inertial>
    <visual>
      <origin xyz="0 0 0" rpy="0 0 0" />
      <geometry>
        <box size="0.01 0.01 0.004" />
      </geometry>
      <material name="blue">
        <color rgba="0 0 1 1" />
      </material>
    </visual>
    <collision>
      <origin xyz="0 0 0" rpy="0 0 0" />
      <geometry>
        <box size="0.01 0.01 0.004" />
      </geometry>
    </collision>
  </link>
  <joint name="right_ankle_roll_link_sensor_42_joint" type="fixed">
    <parent link="right_ankle_roll_link" />
    <child link="right_ankle_roll_link_sensor_42" />
    <origin xyz="-0.05147572970796883 0.020778575504341767 -0.035409145057201385" rpy="0 0 0" />
  </joint>
  <link name="right_ankle_roll_link_sensor_43">
    <inertial>
      <origin xyz="0 0 0" rpy="0 0 0" />
      <mass value="0.001" />
      <inertia ixx="1e-7" ixy="0" ixz="0" iyy="1e-7" iyz="0" izz="1e-7" />
    </inertial>
    <visual>
      <origin xyz="0 0 0" rpy="0 0 0" />
      <geometry>
        <box size="0.01 0.01 0.004" />
      </geometry>
      <material name="blue">
        <color rgba="0 0 1 1" />
      </material>
    </visual>
    <collision>
      <origin xyz="0 0 0" rpy="0 0 0" />
      <geometry>
        <box size="0.01 0.01 0.004" />
      </geometry>
    </collision>
  </link>
  <joint name="right_ankle_roll_link_sensor_43_joint" type="fixed">
    <parent link="right_ankle_roll_link" />
    <child link="right_ankle_roll_link_sensor_43" />
    <origin xyz="-0.030746168555210698 0.027120595622169324 -0.035409145057201385" rpy="0 0 0" />
  </joint>
  <link name="right_ankle_roll_link_sensor_44">
    <inertial>
      <origin xyz="0 0 0" rpy="0 0 0" />
      <mass value="0.001" />
      <inertia ixx="1e-7" ixy="0" ixz="0" iyy="1e-7" iyz="0" izz="1e-7" />
    </inertial>
    <visual>
      <origin xyz="0 0 0" rpy="0 0 0" />
      <geometry>
        <box size="0.01 0.01 0.004" />
      </geometry>
      <material name="blue">
        <color rgba="0 0 1 1" />
      </material>
    </visual>
    <collision>
      <origin xyz="0 0 0" rpy="0 0 0" />
      <geometry>
        <box size="0.01 0.01 0.004" />
      </geometry>
    </collision>
  </link>
  <joint name="right_ankle_roll_link_sensor_44_joint" type="fixed">
    <parent link="right_ankle_roll_link" />
    <child link="right_ankle_roll_link_sensor_44" />
    <origin xyz="0.0040085836138400565 0.027825747649271593 -0.035409145057201385" rpy="0 0 0" />
  </joint>
  <link name="right_ankle_roll_link_sensor_45">
    <inertial>
      <origin xyz="0 0 0" rpy="0 0 0" />
      <mass value="0.001" />
      <inertia ixx="1e-7" ixy="0" ixz="0" iyy="1e-7" iyz="0" izz="1e-7" />
    </inertial>
    <visual>
      <origin xyz="0 0 0" rpy="0 0 0" />
      <geometry>
        <box size="0.01 0.01 0.004" />
      </geometry>
      <material name="blue">
        <color rgba="0 0 1 1" />
      </material>
    </visual>
    <collision>
      <origin xyz="0 0 0" rpy="0 0 0" />
      <geometry>
        <box size="0.01 0.01 0.004" />
      </geometry>
    </collision>
  </link>
  <joint name="right_ankle_roll_link_sensor_45_joint" type="fixed">
    <parent link="right_ankle_roll_link" />
    <child link="right_ankle_roll_link_sensor_45" />
    <origin xyz="0.03720144045197219 0.028679968604689708 -0.035409145057201385" rpy="0 0 0" />
  </joint>
  <link name="right_ankle_roll_link_sensor_46">
    <inertial>
      <origin xyz="0 0 0" rpy="0 0 0" />
      <mass value="0.001" />
      <inertia ixx="1e-7" ixy="0" ixz="0" iyy="1e-7" iyz="0" izz="1e-7" />
    </inertial>
    <visual>
      <origin xyz="0 0 0" rpy="0 0 0" />
      <geometry>
        <box size="0.01 0.01 0.004" />
      </geometry>
      <material name="blue">
        <color rgba="0 0 1 1" />
      </material>
    </visual>
    <collision>
      <origin xyz="0 0 0" rpy="0 0 0" />
      <geometry>
        <box size="0.01 0.01 0.004" />
      </geometry>
    </collision>
  </link>
  <joint name="right_ankle_roll_link_sensor_46_joint" type="fixed">
    <parent link="right_ankle_roll_link" />
    <child link="right_ankle_roll_link_sensor_46" />
    <origin xyz="0.07093099047943345 0.02619078630258939 -0.035409145057201385" rpy="0 0 0" />
  </joint>
  <link name="right_ankle_roll_link_sensor_47">
    <inertial>
      <origin xyz="0 0 0" rpy="0 0 0" />
      <mass value="0.001" />
      <inertia ixx="1e-7" ixy="0" ixz="0" iyy="1e-7" iyz="0" izz="1e-7" />
    </inertial>
    <visual>
      <origin xyz="0 0 0" rpy="0 0 0" />
      <geometry>
        <box size="0.01 0.01 0.004" />
      </geometry>
      <material name="blue">
        <color rgba="0 0 1 1" />
      </material>
    </visual>
    <collision>
      <origin xyz="0 0 0" rpy="0 0 0" />
      <geometry>
        <box size="0.01 0.01 0.004" />
      </geometry>
    </collision>
  </link>
  <joint name="right_ankle_roll_link_sensor_47_joint" type="fixed">
    <parent link="right_ankle_roll_link" />
    <child link="right_ankle_roll_link_sensor_47" />
    <origin xyz="0.1047684499397711 0.025946323800390976 -0.035409145057201385" rpy="0 0 0" />
  </joint>
  <link name="right_ankle_roll_link_sensor_48">
    <inertial>
      <origin xyz="0 0 0" rpy="0 0 0" />
      <mass value="0.001" />
      <inertia ixx="1e-7" ixy="0" ixz="0" iyy="1e-7" iyz="0" izz="1e-7" />
    </inertial>
    <visual>
      <origin xyz="0 0 0" rpy="0 0 0" />
      <geometry>
        <box size="0.01 0.01 0.004" />
      </geometry>
      <material name="blue">
        <color rgba="0 0 1 1" />
      </material>
    </visual>
    <collision>
      <origin xyz="0 0 0" rpy="0 0 0" />
      <geometry>
        <box size="0.01 0.01 0.004" />
      </geometry>
    </collision>
  </link>
  <joint name="right_ankle_roll_link_sensor_48_joint" type="fixed">
    <parent link="right_ankle_roll_link" />
    <child link="right_ankle_roll_link_sensor_48" />
    <origin xyz="0.1312868744134903 0.023020034655928612 -0.035409145057201385" rpy="0 0 0" />
  </joint>
</robot>